Workbook

Sheet Lab 3
A1: 115.109: Topic 3 Lab Worksheet | K1: Your Name: | M1: Savnit Prasad
A2: Due date: August 17 | D2: Version: 2 (23.07) | F2: Version: 1.2 (13.08) | K2: Student ID: | M2: 26019118
A4: Table 1 | E4: Retail Trade Survey: December 2025 quarter
E5: https://www.stats.govt.nz/information-releases/retail-trade-survey-december-2025-quarter/
A6: Actual retail sales values(1)
A7: By quarter by industry | E7: 1. Figures exclude GST. | K7: $(million)
D9: Series | E9: 2023 | G9: 2024 | O9: 2025
A10: Industry | D10: ref: | E10: Dec | G10: Mar | I10: Jun | K10: Sep | M10: Dec | O10: Mar | Q10: June | S10: Sep | U10: Dec | X10: Task 1: Line Chart: Supermarket sales values Dec23-Dec25
D11: RTTQ | U11: $(million)
A12: Supermarket and grocery stores | D12: S1AAC | E12: 7076 | G12: 6790 | I12: 6507 | K12: 6566 | M12: 7196 | O12: 6943 | Q12: 6736 | S12: 6796 | U12: 7375 | X12: Suggestion: copy cells E12:U12 to the 'Workings tab' and follow instructions there
A13: Specialised food | D13: S1ABC | E13: 544 | G13: 475 | I13: 469 | K13: 456 | M13: 549 | O13: 499 | Q13: 475 | S13: 484 | U13: 590
A14: Liquor | D14: S1ACC | E14: 593 | G14: 545 | I14: 501 | K14: 503 | M14: 612 | O14: 522 | Q14: 480 | S14: 472 | U14: 600
A15: Non-store and commission-based retailing | D15: S1AEC | E15: 597 | G15: 479 | I15: 461 | K15: 489 | M15: 544 | O15: 462 | Q15: 480 | S15: 484 | U15: 560
A16: Department stores | D16: S1AFC | E16: 2190 | G16: 1562 | I16: 1686 | K16: 1531 | M16: 2173 | O16: 1573 | Q16: 1706 | S16: 1615 | U16: 2190
A17: Furniture, floor coverings, houseware, textiles | D17: S1AGC | E17: 863 | G17: 721 | I17: 748 | K17: 753 | M17: 871 | O17: 738 | Q17: 760 | S17: 772 | U17: 910
A18: Hardware, building, and garden supplies | D18: S1AHC | E18: 2926 | G18: 2525 | I18: 2527 | K18: 2565 | M18: 2859 | O18: 2465 | Q18: 2492 | S18: 2600 | U18: 2922
A19: Recreational goods | D19: S1AJC | E19: 944 | G19: 774 | I19: 700 | K19: 647 | M19: 968 | O19: 788 | Q19: 737 | S19: 696 | U19: 1064
A20: Clothing, footwear, and accessories | D20: S1AKC | E20: 1499 | G20: 1191 | I20: 1231 | K20: 1113 | M20: 1500 | O20: 1234 | Q20: 1234 | S20: 1121 | U20: 1552
A21: Electrical and electronic goods | D21: S1ALC | E21: 1000 | G21: 845 | I21: 840 | K21: 847 | M21: 1007 | O21: 847 | Q21: 907 | S21: 969 | U21: 1163
A22: Pharmaceutical and other store-based retailing | D22: S1AMC | E22: 2215 | G22: 1991 | I22: 2006 | K22: 1954 | M22: 2304 | O22: 2141 | Q22: 2139 | S22: 2155 | U22: 2590
A23: Accommodation | D23: S1AUC | E23: 1418 | G23: 1656 | I23: 1139 | K23: 1094 | M23: 1525 | O23: 1710 | Q23: 1208 | S23: 1170 | U23: 1607
A24: Food and beverage services | D24: S1AVC | E24: 4124 | G24: 3965 | I24: 3821 | K24: 3825 | M24: 4254 | O24: 4004 | Q24: 3904 | S24: 4049 | U24: 4431
... A28: All industries total | D28: S1A9C | E28: 32569 | G28: 29956 | I28: 28783 | K28: 28471 | M28: 32629 | O28: 30372 | Q28: 29504 | S28: 29893 | U28: 34232
A30: Percentage change from same quarter previous year(2) | X30: Task 2: Line Chart: Supermarket % change on same quarter previous year
A31: Supermarket and grocery stores | E31: 5.4 | G31: 3.8 | I31: 3.8 | K31: 2.1 | M31: 1.7 | O31: 2.2 | Q31: 3.5 | S31: 3.5 | U31: 2.5 | X31: Suggestion: copy cells E31:U31 to the 'Workings tab' and follow instructions there
A32: Specialised food | E32: -3.9 | G32: 0.6 | I32: 4 | K32: -2.6 | M32: 1 | O32: 4.9 | Q32: 1.2 | S32: 6.2 | U32: 7.3
A33: Liquor | E33: -9.5 | G33: 2.9 | I33: 2.3 | K33: 3.4 | M33: 3.3 | O33: -4.3 | Q33: -4.2 | S33: -6.1 | U33: -2
A34: Non-store and commission-based retailing | E34: -6 | G34: -2.5 | I34: -10.2 | K34: -3.9 | M34: -8.8 | O34: -3.6 | Q34: 4.3 | S34: -1.1 | U34: 2.8
A35: Department stores | E35: -3.6 | G35: -6.3 | I35: -5.1 | K35: -6.1 | M35: -0.8 | O35: 0.7 | Q35: 1.1 | S35: 5.4 | U35: 0.8
A36: Furniture, floor coverings, houseware, textiles | E36: -3.4 | G36: -7.2 | I36: -6.4 | K36: -3.2 | M36: 1 | O36: 2.4 | Q36: 1.6 | S36: 2.5 | U36: 4.4
A37: Hardware, building, and garden supplies | E37: -6.5 | G37: -7.6 | I37: -6.3 | K37: -5.2 | M37: -2.3 | O37: -2.4 | Q37: -1.4 | S37: 1.3 | U37: 2.2
A38: Recreational goods | E38: -6.7 | G38: -3.2 | I38: -5.4 | K38: -8.7 | M38: 2.6 | O38: 1.7 | Q38: 5.2 | S38: 7.5 | U38: 9.9
A39: Clothing, footwear, and accessories | E39: -2.3 | G39: -2.1 | I39: -1.1 | K39: -4.4 | M39: 0.1 | O39: 3.6 | Q39: 0.3 | S39: 0.7 | U39: 3.5
A40: Electrical and electronic goods | E40: -1.2 | G40: -5.3 | I40: -10.4 | K40: -4.8 | M40: 0.6 | O40: 0.3 | Q40: 8 | S40: 14.4 | U40: 15.5
A41: Pharmaceutical and other store-based retailing | E41: 5.9 | G41: 9.4 | I41: 7.2 | K41: 3.3 | M41: 4 | O41: 7.6 | Q41: 6.6 | S41: 10.3 | U41: 12.4
A42: Accommodation | E42: 8.6 | G42: 11.7 | I42: -2.5 | K42: -9.5 | M42: 7.5 | O42: 3.2 | Q42: 6.1 | S42: 7 | U42: 5.4
A43: Food and beverage services | E43: 4.2 | G43: 5.6 | I43: 1.4 | K43: -0.8 | M43: 3.2 | O43: 1 | Q43: 2.2 | S43: 5.9 | U43: 4.1
... A47: All industries total | E47: -0.4 | G47: 0.6 | I47: -1.6 | K47: -2.8 | M47: 0.2 | O47: 1.4 | Q47: 2.5 | S47: 5 | U47: 4.9
A49: Task 3: Complete Percentage Change on previous quarter: Values
A50: Percentage change from previous quarter | W50: Mean | X50: Median | Z50: Which is a better indicator of central tendency for this data: mean or median? (overall)
...

Sheet Workings
C1: PASTE ALL REQUESTED DATA HERE, then delete the blank (formatting) columns D, F, H… to insert individual line charts.
A2: Location: | C2: 45261 | E2: 45352 | G2: 45444 | I2: 45536 | K2: 45627 | M2: 45717 | O2: 45809 | Q2: 45901 | S2: 45992
A3: Task 1: Table 1 row 12 | B3: Actual Supermarket sales values Dec23-Dec25 | C3: 7076 | E3: ='Lab 3'!G12 -> 6790 | G3: ='Lab 3'!I12 -> 6507 | I3: ='Lab 3'!K12 -> 6566 | K3: ='Lab 3'!M12 -> 7196 | M3: ='Lab 3'!O12 -> 6943 | O3: ='Lab 3'!Q12 -> 6736 | Q3: ='Lab 3'!S12 -> 6796 | S3: ='Lab 3'!U12 -> 7375
A4: Task 2: Table 1 row 31 | B4: Supermarket % change on same quarter previous year | C4: ='Lab 3'!E31 -> 5.4 | E4: ='Lab 3'!G31 -> 3.8 | G4: ='Lab 3'!I31 -> 3.8 | I4: ='Lab 3'!K31 -> 2.1 | K4: ='Lab 3'!M31 -> 1.7 | M4: ='Lab 3'!O31 -> 2.2 | O4: ='Lab 3'!Q31 -> 3.5 | Q4: ='Lab 3'!S31 -> 3.5 | S4: ='Lab 3'!U31 -> 2.5
A5: Task 5: Table 2 row 95 | B5: Supermarket sales volumes (3Q 2010 prices) Dec23-Dec25 | C5: ='Lab 3'!E95 -> 5054 | E5: ='Lab 3'!G95 -> 4795 | G5: ='Lab 3'!I95 -> 4605 | I5: ='Lab 3'!K95 -> 4598 | K5: ='Lab 3'!M95 -> 5075 | M5: ='Lab 3'!O95 -> 4788 | O5: ='Lab 3'!Q95 -> 4592 | Q5: ='Lab 3'!S95 -> 4555 | S5: ='Lab 3'!U95 -> 4990
A6: Task 6 Table 2 row 114 | B6: Supermarket % change on same quarter previous year (3Q 2010 prices) | C6: ='Lab 3'!E114 -> -0.4 | E6: ='Lab 3'!G114 -> 1.1 | G6: ='Lab 3'!I114 -> 3.4 | I6: ='Lab 3'!K114 -> 1.1 | K6: ='Lab 3'!M114 -> 0.4 | M6: ='Lab 3'!O114 -> -0.2 | O6: ='Lab 3'!Q114 -> -0.3 | Q6: ='Lab 3'!S114 -> -0.9 | S6: ='Lab 3'!U114 -> -1.7
A7: Create graphs from each row, in separate charts
A8: You can create one 'pretty' graph as per below, then copy and paste that chart and amend the row the chart is pulling data from (eg from C3:S3 for actual sales values, to C4:S4 for % change) - use the formula bar to edit
A9: Make graphs 'pretty' with axis titles - can remove legend if this duplicates chart title
A10: Hint: make sure the X-axis shows the quarters ending March, June…. Excel wil default to 2-monthly axis labels.
A11: → To change axis labels: double-click the axis text, choose Axis Options and change Major units to 3 monthly
A13: → To add axis titles: click on the chart and choose Chart Tools > Design menu option; click on Add Chart Element > Primary Vertical.
A14: → Despite the text being side-ways, you can edit it normally by double-clicking and typing to replace.
A15: Example: raw chart and some modifications:
A30: Example: finished chart (% change on same quarter previous year)
A31: Fixed: x-axis options > units > 3 months
A32: Added: Horizontal and Vertical Axis titles; changed chart title; removed legend
A47: (legend removed since there is only one series: legend would match title)
A49: Insert charts here, and when finished editing, copy back to Lab 3 (as images)

Sheet IRI SKUs
A1: IRI SKUs Ranking Report - All SKUs
A2: Data retreived via Temple plugin
A4: MAT To 19/06/22 | B4: New Zealand Grocery
A5: Brand (Stock Keeping Unit) | B5: Dollars | C5: Units | D5: Dist Num% | E5: Price $/Unit | F5: Highest Weekly Price | G5: Lowest Weekly Price | H5: Markets On Promotion | I5: Promoted Price >= 3 % 9 wks | J5: Non Promoted Price $/Unit >= 3 % 9 wks | K5: Percentage Discount >= 3 % 9 wks | L5: Wks on Promotion >= 3 % 9 wks | M5: Cumulative sales dollars
A6: Total Widgets | B6: 75009312 | C6: 14998461 | D6: 99.075279 | E6: 5.0011339 | F6: 5.3680272 | G6: 4.5155005 | H6: 18 | I6: 4.6115013 | J6: 5.543831 | K6: 9.7795028 | L6: 52 | N6: Total Widgets
A7: Better Super Doopers 1.2kg | B7: 14321003 | C7: 2171901 | D7: 98.859222 | E7: 6.5937642 | F7: 7.2917585 | G7: 5.3416171 | H7: 18 | I7: 6.1972416 | J7: 7.2484084 | K7: 9.0315557 | L7: 50 | M7: =B7 -> 14321003
A8: Better Super Doopers 750g | B8: 10084678 | C8: 2051288 | D8: 98.665092 | E8: 4.9162663 | F8: 5.5779042 | G8: 4.4426928 | H8: 18 | I8: 4.5455706 | J8: 5.4930387 | K8: 10.500063 | L8: 49 | M8: =M7+B8 -> 24405681
A9: Better Super Doopers Bites WildNeon 500g | B9: 5762434.5 | C9: 1002865 | D9: 98.234093 | E9: 5.7459723 | F9: 6.2073464 | G9: 5.4466486 | H9: 18 | I9: 5.5553096 | J9: 5.9510663 | K9: 3.446342 | L9: 47 | M9: =M8+B9 -> 30168116
A10: Best Crunchy Pieces Super 500g | B10: 4294235.5 | C10: 1214490 | D10: 96.804596 | E10: 3.5358344 | F10: 4.0796223 | G10: 2.8428152 | H10: 18 | I10: 3.2280969 | J10: 4.0836399 | K10: 13.389606 | L10: 50 | M10: =M9+B10 -> 34462351
A11: Better Super Doopers 375g | B11: 3308473 | C11: 903122 | D11: 98.30217 | E11: 3.6633733 | F11: 3.8901703 | G11: 3.4987383 | H11: 16 | I11: 3.5116749 | J11: 3.7489732 | K11: 2.2832945 | L11: 38 | M11: =M10+B11 -> 37770824
A12: Best Super Racing Neon 500g | B12: 2625818.8 | C12: 491636 | D12: 96.558884 | E12: 5.3409814 | F12: 5.9896903 | G12: 4.8963885 | H12: 18 | I12: 4.9008403 | J12: 5.8519272 | K12: 8.7312416 | L12: 47 | M12: =M11+B12 -> 40396643
A13: Best Chippies 460g | B13: 2433652.2 | C13: 689067 | D13: 93.723991 | E13: 3.5318079 | F13: 4.1136498 | G13: 2.8103578 | H13: 18 | I13: 3.2214232 | J13: 4.1243464 | K13: 14.366849 | L13: 50 | M13: =M12+B13 -> 42830295
A14: Best Light N Tasty Rice 525g | B14: 2030376.9 | C14: 379272 | D14: 94.366531 | E14: 5.3533529 | F14: 5.9926414 | G14: 4.9502802 | H14: 18 | I14: 4.902387 | J14: 5.8583373 | K14: 8.6199282 | L14: 48 | M14: =M13+B14 -> 44860672
A15: Best Crunchy Pieces Super 300g | B15: 2026266.4 | C15: 838323 | D15: 80.088829 | E15: 2.4170473 | F15: 3.114995 | G15: 1.6867507 | H15: 18 | I15: 2.1504782 | J15: 3.102833 | K15: 22.104804 | L15: 50 | M15: =M14+B15 -> 46886938
A16: Better Super Doopers Rust Free 375g | B16: 1806725.2 | C16: 276119 | D16: 95.31974 | E16: 6.5432848 | F16: 7.3045249 | G16: 6.0557685 | H16: 18 | I16: 6.1069513 | J16: 7.0782605 | K16: 7.5580099 | L16: 52 | M16: =M15+B16 -> 48693664
A17: Fasterod Rolls Original 790g | B17: 1754694 | C17: 216745 | D17: 74.439674 | E17: 8.0956608 | F17: 9.4505062 | G17: 5.9287496 | H17: 14 | I17: 7.514479 | J17: 9.5997222 | K17: 15.667696 | L17: 52 | M17: =M16+B17 -> 50448358
A18: Better Super Doopers Bites Crunchy Lemon 510g | B18: 1601625 | C18: 278089 | D18: 89.377586 | E18: 5.7593972 | F18: 6.2451329 | G18: 5.4304509 | H18: 18 | I18: 5.6209914 | J18: 5.9524365 | K18: 3.2430309 | L18: 45 | M18: =M17+B18 -> 52049982
A19: Better Super Doopers Cholesterol Lowering 440g | B19: 1575385 | C19: 210096 | D19: 93.966515 | E19: 7.4984055 | F19: 8.1211214 | G19: 7.0208645 | H19: 18 | I19: 7.11813 | J19: 7.8769548 | K19: 4.8043855 | L19: 51 | M19: =M18+B19 -> 53625368
... A85: Fasterod Rolls Bean Currant & Circlesond 480g | B85: 0 | C85: 0 | D85: 0 | E85: 0 | F85: 0 | G85: 0 | H85: 0 | I85: 0 | J85: 0 | K85: 0 | L85: 0 | M85: =M84+B85 -> 75009308
C87: Units | E87: Average Price
B88: Mean: | C88: =AVERAGEIF(B7:B86,"<>0",C7:C86) -> 217369 | D88: Mean: | E88: =AVERAGEIF(B7:B86,"<>0",E7:E86) -> 5.3131408
B89: Median | C89: {=MEDIAN(IF(B7:B86<>0,C7:C86))} -> 60353 | D89: Median | E89: {=MEDIAN(IF(B7:B86<>0,E7:E86))} -> 5.4318682
A92: Total units sold above mean price: | B92: =SUMIF(E7:E86,">"&E88,C7:C86) -> 7349610 | D92: Number of products above mean price: | G92: =COUNTIF(E7:E86,">"&E88) -> 44 | I92: Number of products above median price: | L92: =COUNTIF(E7:E86,">"&E89) -> 34
A93: Total units sold below mean price: | B93: =SUMIF(E7:E86,"<="&E88,C7:C86) -> 7648851 | D93: Number of product below mean price: | G93: =COUNTIF(E7:E86,"<="&E88)-COUNTIF(B7:B86,0) -> 25 | I93: Number of products below median price: | L93: =COUNTIF(E7:E86,"<="&E89)-COUNTIF(B7:B86,0) -> 35
A95: Total dollar sales above mean price: | B95: =SUMIF(E7:E86,">"&E88,B7:B86) -> 45894666 | I95: *The alternative, but more clunky way, is to sort the E column in descending order and to use a simple 'count' function.
A96: Total dollar sales below mean price: | B96: =SUMIF(E7:E86,"<="&E88,B7:B86) -> 29114643 | D96: Note these cells are locted in a different order on the Lab 3 sheet

Sheet Lab 4
A1: 115.109 Topic 4 Lab Worksheet: Descriptive Statistics | G1: Your Name: | H1: ='Lab 3'!M1 -> Savnit Prasad
A2: ='Lab 3'!A2 -> Due date: August 17 | E2: ='Lab 3'!F2 -> Version: 1.2 (13.08) | G2: Student ID: | H2: ='Lab 3'!M2 -> 26019118
A4: Before you proceed: please complete the Sustainability Survey yourself, here ===> | F4: https://masseybusiness.asia.qualtrics.com/jfe/form/SV_d0Vcl6mFNp9tUCW
A6: Task 1: Determine the Demographics of the sample in the SustainabilityData sheet (next tab), as follows
A8: 1.1 Gender (column C) | C8: 1 (Male) | D8: 2 (Female) | E8: 3 (Gender diverse) | F8: Total
B9: # Respondents | C9: 449 | D9: 591 | E9: 2 | F9: 1042
B10: % Respondents | C10: =C9/F9*100 -> 43.090211 | D10: =D9/F9*100 -> 56.71785 | E10: =E9/F9*100 -> 0.19193858 | F10: =SUM(C10:E10) -> 100
A11: To construct PivotTable:
B12: For Gender: click on column C of the SustainabilityData tab > Insert > Pivot Table (I started the selection from C4 in the example, however, you can use the entire column. In the pivot table you can later deselect the values you do not want in the table)
B13: Drag field name "Gender" to the Rows box, and again drag field name Gender to the Values box (which changes to "Count of Gender"). Your summary table should now appear.
B14: Copy the frequency counts (Paste Special > Values to the table above, then calculate % of total in cell C19, and copy and Paste Special > Formulas across, to determine % Respondents
A15: Note: you can select multiple columns when you create PivotTables, then swap data in and out of the table. Better yet, duplicate (copy/paste) the PivotTable, and change the data source
A17: 1.2 Age category (column D) | C17: 7 (<18) | D17: 1 (18-24) | E17: 2 (25-34) | F17: 3 (35-44) | G17: 4 (45-54) | H17: 5 (55-64) | I17: 6 (65+) | J17: Total
B18: # Respondents | C18: 1 | D18: 68 | E18: 266 | F18: 220 | G18: 142 | H18: 136 | I18: 209 | J18: =SUM(C18:I18) -> 1042
B19: % Respondents | C19: =C18/$J$18*100 -> 0.09596929 | D19: =D18/$J$18*100 -> 6.5259117 | E19: =E18/$J$18*100 -> 25.527831 | F19: =F18/$J$18*100 -> 21.113244 | G19: =G18/$J$18*100 -> 13.627639 | H19: =H18/$J$18*100 -> 13.051823 | I19: =I18/$J$18*100 -> 20.057582 | J19: =SUM(C19:I19) -> 100
A21: 1.3 Age category column chart and Histogram
B22: Using cells C17:I18 above, create a column chart of the age categories below. In the SustainabilityData sheet, create a Histogram of the Age column, and cut and pate that chart here. Which is a better representation of the data?
B23: If your Column shows two series (a taller series showing C18:I18 and a shorter series showing C19:I19): click on any one of the shorter bars, and press the delete key to remove (and then remove the legend)
B24: The Histogram defaults to some pretty ugly class intervals. Right-click on any one of the bars to bring up the Format Data Series panel, and change Bins from Auto to Bin width = 1 (and adjust the underflow and overflow as per below). [The range is > lower value and <= the upper value.]
A38: 1.4 Income (column CE) (via PivotTable)
A39: Cick on column CE of the SustainabilityData tab > Insert > Pivot Table. Drag field name "Income" to the Rows box, and again drag field name Income to the Values box (which changes to "Count of Income")
A40: Paste Special > Values to row 42 below, then calculkate the % values below
C41: 1: Up to $30,000 | D41: 2: $30,001 - $50,000 | E41: 3: $50,001 - $70,000 | F41: 4: $70,001 - $100,000 | G41: 5: $100,001 - $130,000 | H41: 6: Over $130,000 | I41: 7: Would rather not say | J41: Total
B42: # Respondents | C42: 116 | D42: 167 | E42: 170 | F42: 181 | G42: 132 | H42: 99 | I42: 177 | J42: =SUM(C42:I42) -> 1042
B43: % Respondents | C43: =C42/$J$42*100 -> 11.132438 | D43: =D42/$J$42*100 -> 16.026871 | E43: =E42/$J$42*100 -> 16.314779 | F43: =F42/$J$42*100 -> 17.370441 | G43: =G42/$J$42*100 -> 12.667946 | H43: =H42/$J$42*100 -> 9.5009597 | I43: =I42/$J$42*100 -> 16.986564 | J43: =SUM(C43:I43) -> 100
A46: 1.5 Completion time Boxplot
B47: Create a boxplot of the completion time - using the data in column B of the SustainabilityData sheet. (We have more data here than in Lab 1 Task 3, but with the same problem of outliers.)
B48: Select column B rows 5 to 1046, then go to the 'Statistical' chart group and choose Box and Whisker
B49: Give the chart a proper title and remove the X-axis data labelling (which is often pretty meaningless in Excel's version of the chart), and add an X-axis label "N=1042")
B50: Place chart here: (resize chart to fit) | D50: Optional boxplot: Truncated data (ignoring those over 50 minutes)
A64: 1.6 Ethnicity (SustainabilityData columns F to R)
A65: Ethnicity requires some preparation, because it is a multiple response question (someone could indicate many ethnicities simultaneously)
A66: 1) | B66: In cell SustainabilityData R5 insert this calculation: =IF(Q5=1,MAX(F5:O5),11), and copy down to R1046. What this does:
B67: i) looks at the previous column, which calculates how many ethnicities the respondent has answered
B68: ii) If the count is 1 (only one ethnicity answered), it inserts the largest number [the min value would also work, since Max=Min for only one value)
B69: iii) Otherwise (if the count is more than one) it enters the value 11 (which means "multiple selections")
A70: 2) | B70: In SustainabilityData cell F1048, get the count of the range F5:F1046 [nb: this is a simple count, not countif)
A71: 3) | B71: Copy formula across G1048:O1048. These are total nominated ethnicity, whether 1 or multiple ethnic groups were selected, Copy (Paste Special > Values) here to row 76 of this sheet
A72: 4) | B72: Get a PivotTable of single Ethnicity: In SustainabilityData, click on column R > Insert > Pivot Table (in a new worksheet)
A73: 5) | B73: Drag field name "Ethnicity coded" to the Rows box, and again drag field name Ethnicity coded to the Values box (make sure it says "Count of Ethnicity coded"). Your summary table should now appear.
...

Sheet Sheet5
A3: Row Labels | B3: Count of FirstMentions
A4: Ecostore | B4: 39
A5: Eco store | B5: 28
A6: Countdown | B6: 25
A7: the warehouse | B7: 20
A8: Kathmandu | B8: 19
A9: Warehouse | B9: 16
A10: eco | B10: 15
A11: Countdown | B11: 14
A12: Fonterra | B12: 12
A13: Kathmandu | B13: 11
A14: Mercury | B14: 10
A15: New World | B15: 10
... A313: Levi's | B313: 1
A314: (blank)
A315: Grand Total | B315: 708

Sheet Sheet1
A3: Row Labels | B3: Count of Gender
A4: 1 | B4: 449
A5: 2 | B5: 591
A6: 3 | B6: 2
A7: Grand Total | B7: 1042

Sheet Sheet2
A3: Row Labels | B3: Count of Age
A4: 1 | B4: 68
A5: 2 | B5: 266
A6: 3 | B6: 220
A7: 4 | B7: 142
A8: 5 | B8: 136
A9: 6 | B9: 209
A10: 7 | B10: 1
A11: Grand Total | B11: 1042

Sheet Sheet6
A3: Row Labels | B3: Count of Ethnicity coded
A4: 1 | B4: 676
A5: 2 | B5: 17
A6: 3 | B6: 7
A7: 4 | B7: 3
A8: 5 | B8: 4
A9: 6 | B9: 3
A10: 7 | B10: 45
A11: 8 | B11: 69
A12: 9 | B12: 140
A13: 10 | B13: 17
A14: 11 | B14: 61
A15: Grand Total | B15: 1042

Sheet Sheet3
A3: Row Labels | B3: Count of Household Income
A4: 1 | B4: 116
A5: 2 | B5: 167
A6: 3 | B6: 170
A7: 4 | B7: 181
A8: 5 | B8: 132
A9: 6 | B9: 99
A10: 7 | B10: 177
A11: Grand Total | B11: 1042

Sheet SustainabilityData
A1: Variable Group | F1: Ethnicity | Q1: Ethnicity count | R1: Ethnicity coded | S1: What does sustainability mean to you? (select all that apply) | AH1: What does sustainability mean to you? (ranked order) | AU1: What retail brands come to mind when you think of sustainability? (up to 5 retail brands) | AZ1: Sustainable intentions and behaiour | BF1: Societal Domain: How important is it that a retail business/brand implements or are involved in the following: | BJ1: Environmental Domain | BN1: Supplier Domain | BQ1: Shareholder Domain | BT1: Community Domain | BX1: Employee Domain | CA1: Customer Domain | CF1: Sustainability literacy
A2: Question | B2: Completion Time | C2: Which gender do you identify with? | D2: Which of the following age groups do you fit into:Â | E2: Which region do you live in? | F2: NZ European | G2: Māori | H2: Samoan | I2: Cook Island Maori | J2: Tongan | K2: Niuean | L2: Chinese | M2: Indian | N2: Other(s) (please specify) | O2: Rather not say | P2: Other(s) (please specify) | Q2: Total ethnicities | R2: Ethnicity | S2: Good corporate citizenship | T2: Being environmentally responsible | U2: Targeting zero waste | V2: Being socially responsible | W2: Carbon emission reduction | X2: Using renewable resources | Y2: Protecting ecosystems | Z2: Having actionable plans for climate change | AA2: Having social well-being focus rather than economic progress | AB2: Traceability (can trace where the product has come from "farm to fork") | AC2: Conserving water | AD2: Cleaning our waterways and oceans | AE2: Limiting population and economic growth | AG2: Items Picked | AH2: Good corporate citizenship | AI2: Being environmentally responsible | AJ2: Targeting zero waste | AK2: Being socially responsible | AL2: Carbon emission reduction | AM2: Using renewable resources | AN2: Protecting ecosystems | AO2: Having actionable plans for climate change | AP2: Having social well-being focus rather than economic progress | AQ2: Traceability (can trace where the product has come from "farm to fork") | AR2: Conserving water | AS2: Cleaning our waterways and oceans | AT2: Limiting population and economic growth | AU2: FirstBrand | AV2: SecondBrand | AW2: ThirdBrand | AX2: FourthBrand | AY2: FifthBrand | AZ2: How often do you buy a product that has come from a business that implements sustainable practices? | BA2: How likely are you to pay more for a product that has come from a business that implements sustainable practices? | BB2: I am willing to spend more money in order to buy products that are sustainable | BC2: I believe it is acceptable to spend extra money for products that are sustainable | BD2: Retailers should be required to take back packaging they sell product in (including cardboard, bubble, wrap or filler, polystyrene.. | BE2: There should be a bottle deposit scheme, with customers reimbursed for taking back milk, juice and water bottles to the retailer or a recycle station | BF2: Contributes to solving societal problems | BG2: Supports employee involvement in community programmes: | BH2: Invests in youth related programmes | BI2: Promotes diversity and inclusiveness | BJ2: Reduces energy consumption and emissions | BK2: Recycles (e.g. packaging, fabric, product parts) | BL2: Offers recyclable shopping bags or promotes bring your own bag | BM2: Prevents waste and disposes of waste correctly | BN2: Provide fair terms and conditions for suppliers | BO2: Communicates openly and honestly with stakeholders across the supply chain | BP2: Selects suppliers who have ethical, environmental and socially responsible business practices | BQ2: Ensure economic success of the company by doing 'good' business | BR2: Communicates openly and honestly with shareholders | BS2: Provides sustainable growth and long-term success | BT2: Contributes to the economic development of the region | BU2: Sources products and raw materials locally | BV2: Respects regional values, customs, and culture | BW2: Communicates openly and honestly with the local community | BX2: Creates a fair, open, and equitable work environment | BY2: Develops, supports and trains employees | BZ2: Provides safe working conditions | CA2: Provides opportunities for customers to engage in environmental positive behaviors, e.g. recycling packaging, BYO bags, recycling old products | CB2: Provides information to customers that demonstrates supply chain transparency and product traceability | CC2: Promotes sustainability through accessible reporting and publicly available information | CD2: Provides consumers with an ethical product | CE2: What is your total household income before tax?Â | CF2: I feel capable of helping solve sustainability issues, e.g. environment, societal problems | CG2: I can contribute to a sustainable future by buying products that are made sustainably | CH2: I feel I can help solve sustainability issues by buying sustainable products | CI2: What I purchase as a consumer has an effect on the nation’s future sustainability | CJ2: Each consumer’s behaviour can have a positive effect on society by buying products that are sustainable | CK2: Any individual person can make a difference to the world by choosing products carefully | CL2: I have a good knowledge about sustainability issues | CM2: I know a great deal about sustainability and sustainability matters | CN2: I know a lot about sustainable products and brands sold in the marketplace
A3: Variable coding: Respondent: | B3: Minutes to complete | C3: 1: Male 2: Female 3: Gender diverse | D3: 7: Under 18 1: 18-24 2: 25-34 3: 35-44 4: 45-54 5: 55-64 6: 65+ | E3: 1 Northland 2 Auckland 3 Waikato 4 Bay of Plenty 5 Gisborne 6 Hawkes Bay 7 Taranaki 8 Manawatu-Wanganui 9 Wellington 10 Other North Island 11 West Coast 12 Canterbury 13 Otago 14 Southland 15 Tasman/ Nelson/ Marlborough 16 Other South Island | R3: 1: New Zealand European 2: Māori 3: Samoan 4: Cook Island Maori 5: Tongan 6: Niuean 7: Chinese 8: Indian 9: Other(s) (specify) 10: Rather not say 11: Multiple | S3: These numbers don't mean anything per se (nominal data), just that the item was chosen. You can count how many times each item was chosen individually, but analysing combinations within multi-pick questions is problematic! | AH3: These are rankings from 1=top to 13=bottom. You can calculate mean ranks (or calculate Spearman's rank correlation coefficients), but otherwise ranked data is challenging. | AU3: (Free text) IDK, dunno, none etc removed | AV3: (Free text) | AW3: (Free text) | AX3: (Free text) | AY3: (Free text) | AZ3: 1: Not at all 5: Very often 6: Don't know | BA3: 1: Not likely 5: Very likely | BB3: 1: Strongly disagree 3: Neither disagree nor agree 5: Strongly agree | BC3: 1: Strongly disagree 3: Neither disagree nor agree 5: Strongly agree | BD3: 1: Strongly disagree 3: Neither disagree nor agree 5: Strongly agree | BE3: 1: Strongly disagree 3: Neither disagree nor agree 5: Strongly agree | BF3: 1: Not at all important 5: Extremely Important | BG3: 1: Not at all important 5: Extremely Important | BH3: 1: Not at all important 5: Extremely Important | BI3: 1: Not at all important 5: Extremely Important | BJ3: 1: Not at all important 5: Extremely Important | BK3: 1: Not at all important 5: Extremely Important | BL3: 1: Not at all important 5: Extremely Important | BM3: 1: Not at all important 5: Extremely Important | BN3: 1: Not at all important 5: Extremely Important | BO3: 1: Not at all important 5: Extremely Important | BP3: 1: Not at all important 5: Extremely Important | BQ3: 1: Not at all important 5: Extremely Important | BR3: 1: Not at all important 5: Extremely Important | BS3: 1: Not at all important 5: Extremely Important | BT3: 1: Not at all important 5: Extremely Important | BU3: 1: Not at all important 5: Extremely Important | BV3: 1: Not at all important 5: Extremely Important | BW3: 1: Not at all important 5: Extremely Important | BX3: 1: Not at all important 5: Extremely Important | BY3: 1: Not at all important 5: Extremely Important | BZ3: 1: Not at all important 5: Extremely Important | CA3: 1: Not at all important 5: Extremely Important | CB3: 1: Not at all important 5: Extremely Important | CC3: 1: Not at all important 5: Extremely Important | CD3: 1: Not at all important 5: Extremely Important | CE3: 1: Up to $30,000 2: $30,001 - $50,000 3: $50,001 - $70,000 4: $70,001 - $100,000 5: $100,001 - $130,000 6: Over $130,000 7: Would rather not say | CF3: 1: Strongly disagree 3: Neither disagree nor agree 5: Strongly agree | CG3: 1: Strongly disagree 3: Neither disagree nor agree 5: Strongly agree | CH3: 1: Strongly disagree 3: Neither disagree nor agree 5: Strongly agree | CI3: 1: Strongly disagree 3: Neither disagree nor agree 5: Strongly agree | CJ3: 1: Strongly disagree 3: Neither disagree nor agree 5: Strongly agree | CK3: 1: Strongly disagree 3: Neither disagree nor agree 5: Strongly agree | CL3: 1: Strongly disagree 3: Neither disagree nor agree 5: Strongly agree | CM3: 1: Strongly disagree 3: Neither disagree nor agree 5: Strongly agree | CN3: 1: Strongly disagree 3: Neither disagree nor agree 5: Strongly agree
A4: Variable | B4: Time | C4: Gender | D4: Age | E4: Region | F4: E1 | G4: E2 | H4: E3 | I4: E4 | J4: E5 | K4: E6 | L4: E7 | M4: E8 | N4: E9 | O4: E10 | P4: E11 | Q4: ETot | R4: Ethnicity coded | S4: Corporate citizenship | T4: Enviro responsible | U4: Zero waste | V4: Social responsible | W4: Carbon emissions | X4: Renewables | Y4: Ecosystems | Z4: Climate change | AA4: Social well-being | AB4: Traceability | AC4: Water | AD4: Waterways | AE4: Limiting growth | AF4: Not sure | AG4: Number of Items picked | AH4: Corporate citizenship rank | AI4: Enviro responsible rank | AJ4: Zero waste rank | AK4: Social responsible rank | AL4: Carbon emissions rank | AM4: Renewables rank | AN4: Ecosystems rank | AO4: Climate change rank | AP4: Social well-being rank | AQ4: Traceability rank | AR4: Water rank | AS4: Waterways rank | AT4: Limiting growth rank | AU4: FirstBrand | AV4: SecondBrand | AW4: ThirdBrand | AX4: FourthBrand | AY4: FifthBrand | AZ4: HowOftenBuy | BA4: LikelyPayMore | BB4: WillingPayMore | BC4: AcceptablePayMore | BD4: Return Packaging | BE4: Bottle Deposit scheme | BF4: Solve societal | BG4: Support employees | BH4: Youth | BI4: Diversity | BJ4: Reduces emissions | BK4: Recycles | BL4: Recyclable bag | BM4: Waste | BN4: Fair to suppliers | BO4: Communicate Suppliers | BP4: Ethical suppliers | BQ4: Good business | BR4: Communicate Shareholders | BS4: Sustainable growth | BT4: Economic develop | BU4: Sources locally | BV4: Regional culture | BW4: Communicate community | BX4: Equitable work | BY4: Trains employees | BZ4: Safe work | CA4: Customer enviro | CB4: Inform customer traceability | CC4: Sustainable reporting | CD4: Ethical products | CE4: Household Income | CF4: Capable to solve | CG4: Contribute | CH4: Can help | CI4: Purchase effect | CJ4: Positive effect | CK4: Individual difference | CL4: Good knowledge | CM4: Know sustainability | CN4: Know sustainable brands
A5: P1 | B5: 4.5166667 | C5: 2 | D5: 4 | E5: 2 | F5: 1 | Q5: =COUNT(F5:P5) -> 1 | R5: =IF(Q5=1,MAX(F5:O5),11) -> 1 | T5: 2 | X5: 6 | AD5: 12 | AG5: =COUNT(S5:AE5) -> 3 | AI5: 3 | AM5: 1 | AS5: 2 | AU5: eco | AV5: for good | AZ5: 3 | BA5: 3 | BB5: 3 | BC5: 3 | BD5: 4 | BE5: 4 | BF5: 3 | BG5: 3 | BH5: 3 | BI5: 3 | BJ5: 4 | BK5: 4 | BL5: 3 | BM5: 4 | BN5: 4 | BO5: 4 | BP5: 4 | BQ5: 4 | BR5: 4 | BS5: 4 | BT5: 4 | BU5: 3 | BV5: 4 | BW5: 4 | BX5: 4 | BY5: 4 | BZ5: 4 | CA5: 3 | CB5: 4 | CC5: 3 | CD5: 4 | CE5: 7 | CF5: 3 | CG5: 4 | CH5: 3 | CI5: 4 | CJ5: 4 | CK5: 4 | CL5: 3 | CM5: 3 | CN5: 2
A6: P2 | B6: 31.016667 | C6: 2 | D6: 5 | E6: 11 | F6: 1 | Q6: =COUNT(F6:P6) -> 1 | R6: =IF(Q6=1,MAX(F6:O6),11) -> 1 | T6: 2 | U6: 3 | W6: 5 | X6: 6 | Z6: 8 | AB6: 10 | AD6: 12 | AG6: =COUNT(S6:AE6) -> 7 | AI6: 2 | AJ6: 6 | AL6: 3 | AM6: 1 | AO6: 5 | AQ6: 7 | AS6: 4 | AZ6: 6 | BA6: 3 | BB6: 3 | BC6: 4 | BD6: 4 | BE6: 4 | BF6: 3 | BG6: 4 | BH6: 4 | BI6: 3 | BJ6: 4 | BK6: 4 | BL6: 5 | BM6: 5 | BN6: 4 | BO6: 3 | BP6: 4 | BQ6: 4 | BR6: 4 | BS6: 4 | BT6: 5 | BU6: 5 | BV6: 5 | BW6: 5 | BX6: 5 | BY6: 5 | BZ6: 5 | CA6: 5 | CB6: 5 | CC6: 4 | CD6: 4 | CE6: 1 | CF6: 3 | CG6: 4 | CH6: 3 | CI6: 4 | CJ6: 4 | CK6: 4 | CL6: 2 | CM6: 1 | CN6: 2
A7: P3 | B7: 13.683333 | C7: 2 | D7: 4 | E7: 12 | F7: 1 | Q7: =COUNT(F7:P7) -> 1 | R7: =IF(Q7=1,MAX(F7:O7),11) -> 1 | T7: 2 | Y7: 7 | Z7: 8 | AC7: 11 | AD7: 12 | AG7: =COUNT(S7:AE7) -> 5 | AI7: 1 | AN7: 3 | AO7: 2 | AR7: 4 | AS7: 5 | AU7: Kowtow | AV7: Yu Mei | AW7: As Colour | AX7: All Birds | AY7: Penny Sage | AZ7: 4 | BA7: 5 | BB7: 5 | BC7: 5 | BD7: 5 | BE7: 5 | BF7: 4 | BG7: 4 | BH7: 5 | BI7: 5 | BJ7: 5 | BK7: 5 | BL7: 5 | BM7: 5 | BN7: 5 | BO7: 5 | BP7: 5 | BQ7: 5 | BR7: 5 | BS7: 5 | BT7: 5 | BU7: 5 | BV7: 5 | BW7: 5 | BX7: 5 | BY7: 5 | BZ7: 5 | CA7: 5 | CB7: 5 | CC7: 5 | CD7: 5 | CE7: 1 | CF7: 5 | CG7: 5 | CH7: 5 | CI7: 5 | CJ7: 5 | CK7: 5 | CL7: 3 | CM7: 3 | CN7: 3
A8: P4 | B8: 12.65 | C8: 1 | D8: 4 | E8: 9 | F8: 1 | Q8: =COUNT(F8:P8) -> 1 | R8: =IF(Q8=1,MAX(F8:O8),11) -> 1 | T8: 2 | W8: 5 | X8: 6 | AG8: =COUNT(S8:AE8) -> 3 | AI8: 2 | AL8: 3 | AM8: 1 | AZ8: 6 | BA8: 3 | BB8: 3 | BC8: 3 | BD8: 3 | BE8: 3 | BF8: 3 | BG8: 3 | BH8: 3 | BI8: 3 | BJ8: 3 | BK8: 3 | BL8: 3 | BM8: 3 | BN8: 3 | BO8: 3 | BP8: 3 | BQ8: 3 | BR8: 3 | BS8: 3 | BT8: 3 | BU8: 3 | BV8: 3 | BW8: 3 | BX8: 3 | BY8: 3 | BZ8: 3 | CA8: 3 | CB8: 3 | CC8: 3 | CD8: 3 | CE8: 6 | CF8: 3 | CG8: 3 | CH8: 3 | CI8: 3 | CJ8: 3 | CK8: 3 | CL8: 2 | CM8: 2 | CN8: 2
A9: P5 | B9: 13.083333 | C9: 1 | D9: 4 | E9: 4 | F9: 1 | Q9: =COUNT(F9:P9) -> 1 | R9: =IF(Q9=1,MAX(F9:O9),11) -> 1 | T9: 2 | U9: 3 | W9: 5 | X9: 6 | Y9: 7 | Z9: 8 | AB9: 10 | AE9: 13 | AG9: =COUNT(S9:AE9) -> 8 | AI9: 1 | AJ9: 7 | AL9: 2 | AM9: 6 | AN9: 3 | AO9: 4 | AQ9: 5 | AT9: 8 | AU9: Countdown | AZ9: 6 | BA9: 3 | BB9: 3 | BC9: 3 | BD9: 5 | BE9: 5 | BF9: 3 | BG9: 5 | BH9: 4 | BI9: 4 | BJ9: 5 | BK9: 5 | BL9: 5 | BM9: 5 | BN9: 5 | BO9: 5 | BP9: 5 | BQ9: 5 | BR9: 5 | BS9: 5 | BT9: 4 | BU9: 4 | BV9: 5 | BW9: 5 | BX9: 5 | BY9: 5 | BZ9: 5 | CA9: 5 | CB9: 5 | CC9: 5 | CD9: 5 | CE9: 1 | CF9: 3 | CG9: 4 | CH9: 4 | CI9: 3 | CJ9: 4 | CK9: 4 | CL9: 3 | CM9: 2 | CN9: 2
A10: P6 | B10: 7.15 | C10: 2 | D10: 2 | E10: 2 | L10: 7 | Q10: =COUNT(F10:P10) -> 1 | R10: =IF(Q10=1,MAX(F10:O10),11) -> 7 | T10: 2 | V10: 4 | Y10: 7 | AG10: =COUNT(S10:AE10) -> 3 | AI10: 2 | AK10: 3 | AN10: 1 | AZ10: 2 | BA10: 3 | BB10: 3 | BC10: 4 | BD10: 4 | BE10: 5 | BF10: 3 | BG10: 4 | BH10: 3 | BI10: 4 | BJ10: 4 | BK10: 4 | BL10: 4 | BM10: 4 | BN10: 4 | BO10: 4 | BP10: 4 | BQ10: 4 | BR10: 4 | BS10: 4 | BT10: 4 | BU10: 4 | BV10: 4 | BW10: 4 | BX10: 5 | BY10: 5 | BZ10: 5 | CA10: 4 | CB10: 3 | CC10: 4 | CD10: 3 | CE10: 4 | CF10: 3 | CG10: 3 | CH10: 4 | CI10: 4 | CJ10: 4 | CK10: 4 | CL10: 3 | CM10: 3 | CN10: 3
A11: P7 | B11: 11.766667 | C11: 2 | D11: 6 | E11: 8 | F11: 1 | Q11: =COUNT(F11:P11) -> 1 | R11: =IF(Q11=1,MAX(F11:O11),11) -> 1 | T11: 2 | V11: 4 | Y11: 7 | AB11: 10 | AD11: 12 | AG11: =COUNT(S11:AE11) -> 5 | AI11: 1 | AK11: 5 | AN11: 4 | AQ11: 2 | AS11: 3 | AU11: Fontana | AZ11: 6 | BA11: 3 | BB11: 3 | BC11: 2 | BD11: 4 | BE11: 5 | BF11: 1 | BG11: 4 | BH11: 5 | BI11: 2 | BJ11: 4 | BK11: 5 | BL11: 5 | BM11: 5 | BN11: 4 | BO11: 5 | BP11: 3 | BQ11: 3 | BR11: 4 | BS11: 5 | BT11: 5 | BU11: 4 | BV11: 4 | BW11: 4 | BX11: 5 | BY11: 5 | BZ11: 5 | CA11: 4 | CB11: 3 | CC11: 3 | CD11: 3 | CE11: 1 | CF11: 3 | CG11: 4 | CH11: 3 | CI11: 3 | CJ11: 3 | CK11: 4 | CL11: 1 | CM11: 1 | CN11: 2
A12: P8 | B12: 15.866667 | C12: 2 | D12: 2 | E12: 9 | L12: 7 | Q12: =COUNT(F12:P12) -> 1 | R12: =IF(Q12=1,MAX(F12:O12),11) -> 7 | T12: 2 | V12: 4 | W12: 5 | X12: 6 | Y12: 7 | AG12: =COUNT(S12:AE12) -> 5 | AI12: 5 | AK12: 4 | AL12: 1 | AM12: 2 | AN12: 3 | AU12: Ecostore | AZ12: 4 | BA12: 4 | BB12: 4 | BC12: 3 | BD12: 5 | BE12: 4 | BF12: 4 | BG12: 3 | BH12: 2 | BI12: 2 | BJ12: 4 | BK12: 4 | BL12: 4 | BM12: 4 | BN12: 4 | BO12: 4 | BP12: 4 | BQ12: 4 | BR12: 4 | BS12: 4 | BT12: 4 | BU12: 3 | BV12: 3 | BW12: 3 | BX12: 4 | BY12: 4 | BZ12: 4 | CA12: 5 | CB12: 3 | CC12: 3 | CD12: 5 | CE12: 7 | CF12: 4 | CG12: 4 | CH12: 4 | CI12: 4 | CJ12: 4 | CK12: 4 | CL12: 4 | CM12: 4 | CN12: 4
A13: P9 | B13: 7.6 | C13: 2 | D13: 5 | E13: 9 | F13: 1 | Q13: =COUNT(F13:P13) -> 1 | R13: =IF(Q13=1,MAX(F13:O13),11) -> 1 | T13: 2 | U13: 3 | V13: 4 | W13: 5 | X13: 6 | Y13: 7 | Z13: 8 | AA13: 9 | AB13: 10 | AC13: 11 | AD13: 12 | AG13: =COUNT(S13:AE13) -> 11 | AI13: 9 | AJ13: 8 | AK13: 10 | AL13: 7 | AM13: 4 | AN13: 3 | AO13: 6 | AP13: 1 | AQ13: 11 | AR13: 2 | AS13: 5 | AZ13: 3 | BA13: 2 | BB13: 2 | BC13: 3 | BD13: 3 | BE13: 4 | BF13: 4 | BG13: 3 | BH13: 3 | BI13: 5 | BJ13: 5 | BK13: 5 | BL13: 5 | BM13: 5 | BN13: 5 | BO13: 5 | BP13: 5 | BQ13: 4 | BR13: 5 | BS13: 5 | BT13: 4 | BU13: 3 | BV13: 4 | BW13: 4 | BX13: 5 | BY13: 5 | BZ13: 5 | CA13: 4 | CB13: 4 | CC13: 4 | CD13: 4 | CE13: 3 | CF13: 4 | CG13: 4 | CH13: 4 | CI13: 4 | CJ13: 4 | CK13: 4 | CL13: 2 | CM13: 2 | CN13: 2
A14: P10 | B14: 9.9666667 | C14: 1 | D14: 1 | E14: 3 | F14: 1 | Q14: =COUNT(F14:P14) -> 1 | R14: =IF(Q14=1,MAX(F14:O14),11) -> 1 | T14: 2 | U14: 3 | W14: 5 | X14: 6 | Y14: 7 | AC14: 11 | AD14: 12 | AG14: =COUNT(S14:AE14) -> 7 | AI14: 1 | AJ14: 5 | AL14: 2 | AM14: 3 | AN14: 4 | AR14: 6 | AS14: 7 | AZ14: 4 | BA14: 4 | BB14: 4 | BC14: 5 | BD14: 2 | BE14: 5 | BF14: 4 | BG14: 4 | BH14: 4 | BI14: 5 | BJ14: 5 | BK14: 5 | BL14: 5 | BM14: 5 | BN14: 4 | BO14: 4 | BP14: 5 | BQ14: 4 | BR14: 5 | BS14: 5 | BT14: 4 | BU14: 4 | BV14: 4 | BW14: 5 | BX14: 4 | BY14: 5 | BZ14: 5 | CA14: 5 | CB14: 4 | CC14: 5 | CD14: 4 | CE14: 3 | CF14: 3 | CG14: 5 | CH14: 4 | CI14: 5 | CJ14: 4 | CK14: 4 | CL14: 4 | CM14: 4 | CN14: 2
A15: P11 | B15: 15.933333 | C15: 1 | D15: 2 | E15: 2 | F15: 1 | N15: 9 | P15: Australian | Q15: =COUNT(F15:P15) -> 2 | R15: =IF(Q15=1,MAX(F15:O15),11) -> 11 | S15: 1 | T15: 2 | V15: 4 | X15: 6 | AA15: 9 | AB15: 10 | AG15: =COUNT(S15:AE15) -> 6 | AH15: 1 | AI15: 6 | AK15: 2 | AM15: 3 | AP15: 5 | AQ15: 4 | AU15: Eco store | AV15: Countdown | AZ15: 4 | BA15: 4 | BB15: 4 | BC15: 4 | BD15: 5 | BE15: 2 | BF15: 3 | BG15: 3 | BH15: 3 | BI15: 3 | BJ15: 4 | BK15: 5 | BL15: 4 | BM15: 4 | BN15: 3 | BO15: 5 | BP15: 4 | BQ15: 4 | BR15: 5 | BS15: 4 | BT15: 4 | BU15: 4 | BV15: 4 | BW15: 4 | BX15: 4 | BY15: 5 | BZ15: 4 | CA15: 4 | CB15: 4 | CC15: 5 | CD15: 4 | CE15: 6 | CF15: 4 | CG15: 3 | CH15: 2 | CI15: 5 | CJ15: 2 | CK15: 4 | CL15: 4 | CM15: 5 | CN15: 5
A16: P12 | B16: 7.6166667 | C16: 2 | D16: 1 | E16: 3 | F16: 1 | Q16: =COUNT(F16:P16) -> 1 | R16: =IF(Q16=1,MAX(F16:O16),11) -> 1 | T16: 2 | U16: 3 | W16: 5 | X16: 6 | Z16: 8 | AA16: 9 | AE16: 13 | AG16: =COUNT(S16:AE16) -> 7 | AI16: 1 | AJ16: 7 | AL16: 2 | AM16: 3 | AO16: 4 | AP16: 6 | AT16: 5 | AZ16: 6 | BA16: 4 | BB16: 4 | BC16: 5 | BD16: 4 | BE16: 5 | BF16: 3 | BG16: 4 | BH16: 3 | BI16: 3 | BJ16: 4 | BK16: 4 | BL16: 3 | BM16: 4 | BN16: 3 | BO16: 3 | BP16: 3 | BQ16: 4 | BR16: 3 | BS16: 4 | BT16: 3 | BU16: 3 | BV16: 4 | BW16: 3 | BX16: 2 | BY16: 3 | BZ16: 4 | CA16: 3 | CB16: 2 | CC16: 4 | CD16: 5 | CE16: 7 | CF16: 3 | CG16: 4 | CH16: 2 | CI16: 4 | CJ16: 4 | CK16: 4 | CL16: 2 | CM16: 2 | CN16: 3
A17: P13 | B17: 6.3 | C17: 2 | D17: 6 | E17: 7 | F17: 1 | Q17: =COUNT(F17:P17) -> 1 | R17: =IF(Q17=1,MAX(F17:O17),11) -> 1 | V17: 4 | W17: 5 | AB17: 10 | AD17: 12 | AG17: =COUNT(S17:AE17) -> 4 | AK17: 2 | AL17: 4 | AQ17: 1 | AS17: 3 | AU17: recycle plastic | AV17: milk | AZ17: 5 | BA17: 3 | BB17: 3 | BC17: 3 | BD17: 4 | BE17: 5 | BF17: 5 | BG17: 5 | BH17: 5 | BI17: 4 | BJ17: 5 | BK17: 5 | BL17: 5 | BM17: 5 | BN17: 5 | BO17: 5 | BP17: 5 | BQ17: 5 | BR17: 5 | BS17: 5 | BT17: 5 | BU17: 5 | BV17: 5 | BW17: 5 | BX17: 5 | BY17: 5 | BZ17: 5 | CA17: 5 | CB17: 5 | CC17: 5 | CD17: 5 | CE17: 1 | CF17: 4 | CG17: 4 | CH17: 5 | CI17: 4 | CJ17: 5 | CK17: 5 | CL17: 4 | CM17: 5 | CN17: 5
A18: P14 | B18: 14.716667 | C18: 1 | D18: 1 | E18: 12 | F18: 1 | Q18: =COUNT(F18:P18) -> 1 | R18: =IF(Q18=1,MAX(F18:O18),11) -> 1 | T18: 2 | Z18: 8 | AG18: =COUNT(S18:AE18) -> 2 | AI18: 1 | AO18: 2 | AZ18: 2 | BA18: 3 | BB18: 3 | BC18: 3 | BD18: 4 | BE18: 5 | BF18: 4 | BG18: 4 | BH18: 5 | BI18: 4 | BJ18: 4 | BK18: 5 | BL18: 5 | BM18: 4 | BN18: 3 | BO18: 3 | BP18: 4 | BQ18: 4 | BR18: 4 | BS18: 4 | BT18: 4 | BU18: 4 | BV18: 4 | BW18: 4 | BX18: 4 | BY18: 4 | BZ18: 4 | CA18: 4 | CB18: 4 | CC18: 4 | CD18: 4 | CE18: 3 | CF18: 3 | CG18: 3 | CH18: 3 | CI18: 3 | CJ18: 3 | CK18: 4 | CL18: 4 | CM18: 3 | CN18: 2
A19: P15 | B19: 16.65 | C19: 2 | D19: 1 | E19: 8 | F19: 1 | Q19: =COUNT(F19:P19) -> 1 | R19: =IF(Q19=1,MAX(F19:O19),11) -> 1 | T19: 2 | U19: 3 | V19: 4 | Y19: 7 | AA19: 9 | AE19: 13 | AG19: =COUNT(S19:AE19) -> 6 | AI19: 3 | AJ19: 1 | AK19: 4 | AN19: 2 | AP19: 6 | AT19: 5 | AU19: Countdown | AV19: New world | AZ19: 3 | BA19: 4 | BB19: 4 | BC19: 4 | BD19: 3 | BE19: 5 | BF19: 4 | BG19: 4 | BH19: 5 | BI19: 5 | BJ19: 4 | BK19: 5 | BL19: 5 | BM19: 5 | BN19: 3 | BO19: 5 | BP19: 4 | BQ19: 5 | BR19: 5 | BS19: 4 | BT19: 4 | BU19: 4 | BV19: 5 | BW19: 5 | BX19: 5 | BY19: 5 | BZ19: 5 | CA19: 5 | CB19: 3 | CC19: 3 | CD19: 4 | CE19: 3 | CF19: 5 | CG19: 5 | CH19: 4 | CI19: 5 | CJ19: 5 | CK19: 5 | CL19: 3 | CM19: 2 | CN19: 2
A20: P16 | B20: 6.6833333 | C20: 1 | D20: 2 | E20: 9 | F20: 1 | Q20: =COUNT(F20:P20) -> 1 | R20: =IF(Q20=1,MAX(F20:O20),11) -> 1 | T20: 2 | V20: 4 | X20: 6 | Y20: 7 | AA20: 9 | AB20: 10 | AD20: 12 | AG20: =COUNT(S20:AE20) -> 7 | AI20: 1 | AK20: 2 | AM20: 6 | AN20: 5 | AP20: 3 | AQ20: 4 | AS20: 7 | AU20: New World | AV20: The Warehouse | AW20: Countdown | AZ20: 4 | BA20: 3 | BB20: 3 | BC20: 3 | BD20: 4 | BE20: 4 | BF20: 3 | BG20: 4 | BH20: 3 | BI20: 4 | BJ20: 4 | BK20: 4 | BL20: 4 | BM20: 4 | BN20: 4 | BO20: 4 | BP20: 4 | BQ20: 3 | BR20: 4 | BS20: 4 | BT20: 3 | BU20: 4 | BV20: 3 | BW20: 4 | BX20: 4 | BY20: 4 | BZ20: 4 | CA20: 4 | CB20: 4 | CC20: 4 | CD20: 4 | CE20: 2 | CF20: 4 | CG20: 4 | CH20: 4 | CI20: 4 | CJ20: 4 | CK20: 5 | CL20: 4 | CM20: 4 | CN20: 4
A21: P17 | B21: 17.9 | C21: 2 | D21: 6 | E21: 8 | F21: 1 | Q21: =COUNT(F21:P21) -> 1 | R21: =IF(Q21=1,MAX(F21:O21),11) -> 1 | S21: 1 | T21: 2 | U21: 3 | V21: 4 | W21: 5 | X21: 6 | AB21: 10 | AC21: 11 | AD21: 12 | AG21: =COUNT(S21:AE21) -> 9 | AH21: 9 | AI21: 6 | AJ21: 5 | AK21: 1 | AL21: 7 | AM21: 8 | AQ21: 2 | AR21: 3 | AS21: 4 | AU21: Sara | AV21: Schetcher | AW21: Hellabys | AX21: Muzuno | AY21: Asics | AZ21: 5 | BA21: 4 | BB21: 4 | BC21: 4 | BD21: 5 | BE21: 5 | BF21: 5 | BG21: 5 | BH21: 5 | BI21: 5 | BJ21: 5 | BK21: 5 | BL21: 5 | BM21: 5 | BN21: 5 | BO21: 5 | BP21: 5 | BQ21: 5 | BR21: 5 | BS21: 5 | BT21: 5 | BU21: 5 | BV21: 5 | BW21: 5 | BX21: 5 | BY21: 5 | BZ21: 5 | CA21: 5 | CB21: 5 | CC21: 5 | CD21: 5 | CE21: 2 | CF21: 5 | CG21: 5 | CH21: 5 | CI21: 5 | CJ21: 5 | CK21: 5 | CL21: 3 | CM21: 3 | CN21: 3
A22: P18 | B22: 16.983333 | C22: 2 | D22: 2 | E22: 3 | F22: 1 | G22: 2 | Q22: =COUNT(F22:P22) -> 2 | R22: =IF(Q22=1,MAX(F22:O22),11) -> 11 | T22: 2 | U22: 3 | W22: 5 | X22: 6 | Z22: 8 | AG22: =COUNT(S22:AE22) -> 5 | AI22: 1 | AJ22: 3 | AL22: 2 | AM22: 4 | AO22: 5 | AZ22: 3 | BA22: 2 | BB22: 3 | BC22: 3 | BD22: 3 | BE22: 3 | BF22: 3 | BG22: 3 | BH22: 3 | BI22: 3 | BJ22: 3 | BK22: 3 | BL22: 3 | BM22: 3 | BN22: 3 | BO22: 3 | BP22: 3 | BQ22: 3 | BR22: 3 | BS22: 3 | BT22: 3 | BU22: 3 | BV22: 3 | BW22: 3 | BX22: 3 | BY22: 3 | BZ22: 3 | CA22: 3 | CB22: 3 | CC22: 3 | CD22: 3 | CE22: 7 | CF22: 4 | CG22: 3 | CH22: 4 | CI22: 3 | CJ22: 1 | CK22: 5 | CL22: 2 | CM22: 3 | CN22: 2
A23: P19 | B23: 6.6833333 | C23: 2 | D23: 2 | E23: 15 | F23: 1 | Q23: =COUNT(F23:P23) -> 1 | R23: =IF(Q23=1,MAX(F23:O23),11) -> 1 | AF23: 14 | AG23: =COUNT(S23:AE23) -> 0 | AZ23: 6 | BA23: 3 | BB23: 3 | BC23: 3 | BD23: 3 | BE23: 3 | BF23: 3 | BG23: 3 | BH23: 3 | BI23: 3 | BJ23: 3 | BK23: 3 | BL23: 3 | BM23: 3 | BN23: 5 | BO23: 5 | BP23: 3 | BQ23: 3 | BR23: 5 | BS23: 5 | BT23: 3 | BU23: 5 | BV23: 5 | BW23: 5 | BX23: 5 | BY23: 5 | BZ23: 5 | CA23: 3 | CB23: 5 | CC23: 3 | CD23: 5 | CE23: 7 | CF23: 3 | CG23: 3 | CH23: 3 | CI23: 3 | CJ23: 3 | CK23: 3 | CL23: 3 | CM23: 3 | CN23: 3
A24: P20 | B24: 8.6 | C24: 2 | D24: 4 | E24: 2 | F24: 1 | Q24: =COUNT(F24:P24) -> 1 | R24: =IF(Q24=1,MAX(F24:O24),11) -> 1 | T24: 2 | U24: 3 | AA24: 9 | AG24: =COUNT(S24:AE24) -> 3 | AI24: 1 | AJ24: 2 | AP24: 3 | AZ24: 6 | BA24: 4 | BB24: 3 | BC24: 4 | BD24: 4 | BE24: 4 | BF24: 3 | BG24: 4 | BH24: 3 | BI24: 3 | BJ24: 4 | BK24: 4 | BL24: 4 | BM24: 4 | BN24: 3 | BO24: 3 | BP24: 3 | BQ24: 3 | BR24: 3 | BS24: 3 | BT24: 5 | BU24: 5 | BV24: 5 | BW24: 5 | BX24: 5 | BY24: 5 | BZ24: 5 | CA24: 5 | CB24: 5 | CC24: 5 | CD24: 5 | CE24: 7 | CF24: 3 | CG24: 3 | CH24: 3 | CI24: 3 | CJ24: 3 | CK24: 3 | CL24: 3 | CM24: 3 | CN24: 3
A25: P21 | B25: 13.683333 | C25: 2 | D25: 2 | E25: 2 | F25: 1 | Q25: =COUNT(F25:P25) -> 1 | R25: =IF(Q25=1,MAX(F25:O25),11) -> 1 | T25: 2 | U25: 3 | V25: 4 | X25: 6 | Z25: 8 | AB25: 10 | AG25: =COUNT(S25:AE25) -> 6 | AI25: 5 | AJ25: 2 | AK25: 4 | AM25: 3 | AO25: 6 | AQ25: 1 | AU25: Kowtow | AV25: Witchery | AW25: Ecostore | AX25: Trilogy | AY25: Cotton On | AZ25: 4 | BA25: 4 | BB25: 4 | BC25: 4 | BD25: 4 | BE25: 4 | BF25: 4 | BG25: 3 | BH25: 4 | BI25: 5 | BJ25: 4 | BK25: 5 | BL25: 5 | BM25: 5 | BN25: 5 | BO25: 5 | BP25: 5 | BQ25: 4 | BR25: 4 | BS25: 4 | BT25: 3 | BU25: 4 | BV25: 4 | BW25: 4 | BX25: 5 | BY25: 5 | BZ25: 5 | CA25: 4 | CB25: 4 | CC25: 4 | CD25: 4 | CE25: 5 | CF25: 3 | CG25: 4 | CH25: 3 | CI25: 3 | CJ25: 4 | CK25: 4 | CL25: 3 | CM25: 3 | CN25: 3
A26: P22 | B26: 11.416667 | C26: 2 | D26: 2 | E26: 12 | F26: 1 | Q26: =COUNT(F26:P26) -> 1 | R26: =IF(Q26=1,MAX(F26:O26),11) -> 1 | T26: 2 | U26: 3 | V26: 4 | W26: 5 | X26: 6 | Y26: 7 | Z26: 8 | AB26: 10 | AC26: 11 | AD26: 12 | AG26: =COUNT(S26:AE26) -> 10 | AI26: 1 | AJ26: 5 | AK26: 3 | AL26: 9 | AM26: 2 | AN26: 7 | AO26: 10 | AQ26: 6 | AR26: 4 | AS26: 8 | AU26: ITM | AV26: The body shop | AW26: Eco store | AZ26: 6 | BA26: 4 | BB26: 4 | BC26: 4 | BD26: 4 | BE26: 3 | BF26: 4 | BG26: 3 | BH26: 4 | BI26: 5 | BJ26: 4 | BK26: 5 | BL26: 5 | BM26: 5 | BN26: 4 | BO26: 4 | BP26: 5 | BQ26: 5 | BR26: 5 | BS26: 4 | BT26: 5 | BU26: 5 | BV26: 4 | BW26: 4 | BX26: 5 | BY26: 5 | BZ26: 5 | CA26: 5 | CB26: 5 | CC26: 5 | CD26: 5 | CE26: 3 | CF26: 3 | CG26: 4 | CH26: 4 | CI26: 3 | CJ26: 4 | CK26: 5 | CL26: 3 | CM26: 3 | CN26: 3
A27: P23 | B27: 6.2 | C27: 2 | D27: 2 | E27: 12 | F27: 1 | Q27: =COUNT(F27:P27) -> 1 | R27: =IF(Q27=1,MAX(F27:O27),11) -> 1 | V27: 4 | AG27: =COUNT(S27:AE27) -> 1 | AK27: 1 | AZ27: 3 | BA27: 2 | BB27: 3 | BC27: 3 | BD27: 2 | BE27: 5 | BF27: 3 | BG27: 4 | BH27: 3 | BI27: 4 | BJ27: 3 | BK27: 3 | BL27: 3 | BM27: 4 | BN27: 4 | BO27: 4 | BP27: 3 | BQ27: 3 | BR27: 3 | BS27: 4 | BT27: 4 | BU27: 3 | BV27: 4 | BW27: 5 | BX27: 5 | BY27: 5 | BZ27: 5 | CA27: 3 | CB27: 5 | CC27: 5 | CD27: 5 | CE27: 2 | CF27: 3 | CG27: 4 | CH27: 3 | CI27: 2 | CJ27: 4 | CK27: 4 | CL27: 3 | CM27: 1 | CN27: 3
A28: P24 | B28: 14.4 | C28: 1 | D28: 5 | E28: 2 | F28: 1 | Q28: =COUNT(F28:P28) -> 1 | R28: =IF(Q28=1,MAX(F28:O28),11) -> 1 | S28: 1 | AG28: =COUNT(S28:AE28) -> 1 | AH28: 1 | AZ28: 5 | BA28: 4 | BB28: 4 | BC28: 4 | BD28: 3 | BE28: 4 | BF28: 4 | BG28: 5 | BH28: 5 | BI28: 4 | BJ28: 4 | BK28: 4 | BL28: 3 | BM28: 3 | BN28: 4 | BO28: 4 | BP28: 5 | BQ28: 4 | BR28: 4 | BS28: 4 | BT28: 4 | BU28: 4 | BV28: 4 | BW28: 4 | BX28: 4 | BY28: 4 | BZ28: 4 | CA28: 4 | CB28: 3 | CC28: 4 | CD28: 4 | CE28: 4 | CF28: 4 | CG28: 5 | CH28: 4 | CI28: 4 | CJ28: 4 | CK28: 4 | CL28: 4 | CM28: 4 | CN28: 4
A29: P25 | B29: 10.533333 | C29: 2 | D29: 2 | E29: 8 | F29: 1 | Q29: =COUNT(F29:P29) -> 1 | R29: =IF(Q29=1,MAX(F29:O29),11) -> 1 | T29: 2 | U29: 3 | V29: 4 | W29: 5 | X29: 6 | Y29: 7 | Z29: 8 | AB29: 10 | AC29: 11 | AD29: 12 | AE29: 13 | AG29: =COUNT(S29:AE29) -> 11 | AI29: 1 | AJ29: 10 | AK29: 11 | AL29: 2 | AM29: 3 | AN29: 4 | AO29: 5 | AQ29: 6 | AR29: 9 | AS29: 7 | AT29: 8 | AU29: BMW | AV29: Westpac | AW29: Fonterra | AX29: New world | AZ29: 5 | BA29: 5 | BB29: 5 | BC29: 5 | BD29: 3 | BE29: 5 | BF29: 3 | BG29: 4 | BH29: 4 | BI29: 4 | BJ29: 5 | BK29: 5 | BL29: 5 | BM29: 5 | BN29: 5 | BO29: 4 | BP29: 5 | BQ29: 5 | BR29: 5 | BS29: 5 | BT29: 5 | BU29: 5 | BV29: 4 | BW29: 4 | BX29: 5 | BY29: 5 | BZ29: 5 | CA29: 5 | CB29: 5 | CC29: 5 | CD29: 5 | CE29: 5 | CF29: 3 | CG29: 5 | CH29: 5 | CI29: 5 | CJ29: 5 | CK29: 4 | CL29: 3 | CM29: 3 | CN29: 4
A30: P26 | B30: 6.8166667 | C30: 2 | D30: 1 | E30: 2 | L30: 7 | Q30: =COUNT(F30:P30) -> 1 | R30: =IF(Q30=1,MAX(F30:O30),11) -> 7 | X30: 6 | AA30: 9 | AG30: =COUNT(S30:AE30) -> 2 | AM30: 2 | AP30: 1 | AZ30: 2 | BA30: 2 | BB30: 2 | BC30: 2 | BD30: 2 | BE30: 2 | BF30: 2 | BG30: 2 | BH30: 2 | BI30: 2 | BJ30: 2 | BK30: 2 | BL30: 2 | BM30: 2 | BN30: 2 | BO30: 2 | BP30: 2 | BQ30: 2 | BR30: 2 | BS30: 2 | BT30: 2 | BU30: 2 | BV30: 2 | BW30: 2 | BX30: 2 | BY30: 2 | BZ30: 2 | CA30: 2 | CB30: 2 | CC30: 2 | CD30: 2 | CE30: 1 | CF30: 2 | CG30: 2 | CH30: 2 | CI30: 2 | CJ30: 2 | CK30: 2 | CL30: 2 | CM30: 2 | CN30: 2
A31: P27 | B31: 12.333333 | C31: 2 | D31: 2 | E31: 12 | F31: 1 | Q31: =COUNT(F31:P31) -> 1 | R31: =IF(Q31=1,MAX(F31:O31),11) -> 1 | AB31: 10 | AD31: 12 | AG31: =COUNT(S31:AE31) -> 2 | AQ31: 2 | AS31: 1 | AZ31: 4 | BA31: 3 | BB31: 3 | BC31: 3 | BD31: 3 | BE31: 3 | BF31: 2 | BG31: 2 | BH31: 2 | BI31: 2 | BJ31: 3 | BK31: 3 | BL31: 2 | BM31: 4 | BN31: 3 | BO31: 3 | BP31: 2 | BQ31: 4 | BR31: 3 | BS31: 3 | BT31: 2 | BU31: 2 | BV31: 3 | BW31: 3 | BX31: 3 | BY31: 3 | BZ31: 3 | CA31: 3 | CB31: 3 | CC31: 4 | CD31: 3 | CE31: 7 | CF31: 3 | CG31: 3 | CH31: 4 | CI31: 3 | CJ31: 3 | CK31: 4 | CL31: 3 | CM31: 3 | CN31: 3
A32: P28 | B32: 9.8 | C32: 2 | D32: 2 | E32: 2 | M32: 8 | Q32: =COUNT(F32:P32) -> 1 | R32: =IF(Q32=1,MAX(F32:O32),11) -> 8 | T32: 2 | V32: 4 | X32: 6 | Y32: 7 | Z32: 8 | AA32: 9 | AB32: 10 | AE32: 13 | AG32: =COUNT(S32:AE32) -> 8 | AI32: 4 | AK32: 5 | AM32: 6 | AN32: 1 | AO32: 7 | AP32: 2 | AQ32: 8 | AT32: 3 | AZ32: 6 | BA32: 4 | BB32: 4 | BC32: 3 | BD32: 5 | BE32: 5 | BF32: 3 | BG32: 3 | BH32: 3 | BI32: 3 | BJ32: 4 | BK32: 5 | BL32: 4 | BM32: 4 | BN32: 3 | BO32: 4 | BP32: 4 | BQ32: 4 | BR32: 4 | BS32: 4 | BT32: 4 | BU32: 4 | BV32: 4 | BW32: 4 | BX32: 4 | BY32: 4 | BZ32: 4 | CA32: 4 | CB32: 4 | CC32: 4 | CD32: 4 | CE32: 3 | CF32: 4 | CG32: 4 | CH32: 4 | CI32: 4 | CJ32: 4 | CK32: 4 | CL32: 3 | CM32: 3 | CN32: 2
A33: P29 | B33: 10.3 | C33: 2 | D33: 2 | E33: 6 | F33: 1 | Q33: =COUNT(F33:P33) -> 1 | R33: =IF(Q33=1,MAX(F33:O33),11) -> 1 | T33: 2 | U33: 3 | W33: 5 | X33: 6 | Y33: 7 | Z33: 8 | AC33: 11 | AD33: 12 | AG33: =COUNT(S33:AE33) -> 8 | AI33: 1 | AJ33: 6 | AL33: 8 | AM33: 5 | AN33: 4 | AO33: 7 | AR33: 2 | AS33: 3 | AU33: Necessities | AV33: Eco planet | AZ33: 5 | BA33: 3 | BB33: 3 | BC33: 3 | BD33: 3 | BE33: 4 | BF33: 2 | BG33: 3 | BH33: 4 | BI33: 4 | BJ33: 4 | BK33: 4 | BL33: 4 | BM33: 4 | BN33: 4 | BO33: 4 | BP33: 4 | BQ33: 4 | BR33: 4 | BS33: 4 | BT33: 4 | BU33: 4 | BV33: 4 | BW33: 4 | BX33: 5 | BY33: 5 | BZ33: 5 | CA33: 5 | CB33: 5 | CC33: 5 | CD33: 5 | CE33: 2 | CF33: 3 | CG33: 3 | CH33: 3 | CI33: 4 | CJ33: 3 | CK33: 4 | CL33: 3 | CM33: 3 | CN33: 3
A34: P30 | B34: 12.283333 | C34: 2 | D34: 5 | E34: 2 | N34: 9 | P34: South African European | Q34: =COUNT(F34:P34) -> 1 | R34: =IF(Q34=1,MAX(F34:O34),11) -> 9 | X34: 6 | AG34: =COUNT(S34:AE34) -> 1 | AM34: 1 | AZ34: 6 | BA34: 1 | BB34: 1 | BC34: 1 | BD34: 3 | BE34: 5 | BF34: 3 | BG34: 3 | BH34: 4 | BI34: 3 | BJ34: 3 | BK34: 3 | BL34: 4 | BM34: 4 | BN34: 3 | BO34: 3 | BP34: 3 | BQ34: 3 | BR34: 3 | BS34: 3 | BT34: 4 | BU34: 4 | BV34: 4 | BW34: 3 | BX34: 4 | BY34: 4 | BZ34: 5 | CA34: 3 | CB34: 3 | CC34: 3 | CD34: 3 | CE34: 4 | CF34: 1 | CG34: 4 | CH34: 4 | CI34: 2 | CJ34: 4 | CK34: 4 | CL34: 1 | CM34: 1 | CN34: 1
A35: P31 | B35: 16.166667 | C35: 1 | D35: 2 | E35: 13 | F35: 1 | Q35: =COUNT(F35:P35) -> 1 | R35: =IF(Q35=1,MAX(F35:O35),11) -> 1 | T35: 2 | W35: 5 | X35: 6 | Y35: 7 | Z35: 8 | AC35: 11 | AG35: =COUNT(S35:AE35) -> 6 | AI35: 1 | AL35: 5 | AM35: 3 | AN35: 2 | AO35: 4 | AR35: 6 | AZ35: 6 | BA35: 1 | BB35: 1 | BC35: 1 | BD35: 5 | BE35: 5 | BF35: 5 | BG35: 5 | BH35: 3 | BI35: 4 | BJ35: 5 | BK35: 5 | BL35: 5 | BM35: 5 | BN35: 3 | BO35: 4 | BP35: 4 | BQ35: 3 | BR35: 4 | BS35: 4 | BT35: 4 | BU35: 3 | BV35: 4 | BW35: 4 | BX35: 4 | BY35: 3 | BZ35: 3 | CA35: 4 | CB35: 4 | CC35: 4 | CD35: 4 | CE35: 7 | CF35: 5 | CG35: 5 | CH35: 5 | CI35: 5 | CJ35: 5 | CK35: 5 | CL35: 3 | CM35: 2 | CN35: 2
A36: P32 | B36: 11.466667 | C36: 1 | D36: 1 | E36: 3 | F36: 1 | G36: 2 | Q36: =COUNT(F36:P36) -> 2 | R36: =IF(Q36=1,MAX(F36:O36),11) -> 11 | T36: 2 | U36: 3 | X36: 6 | AG36: =COUNT(S36:AE36) -> 3 | AI36: 1 | AJ36: 3 | AM36: 2 | AZ36: 6 | BA36: 3 | BB36: 2 | BC36: 3 | BD36: 4 | BE36: 4 | BF36: 3 | BG36: 4 | BH36: 4 | BI36: 3 | BJ36: 4 | BK36: 5 | BL36: 5 | BM36: 5 | BN36: 4 | BO36: 4 | BP36: 4 | BQ36: 4 | BR36: 4 | BS36: 4 | BT36: 4 | BU36: 3 | BV36: 3 | BW36: 3 | BX36: 3 | BY36: 4 | BZ36: 5 | CA36: 5 | CB36: 4 | CC36: 4 | CD36: 4 | CE36: 3 | CF36: 4 | CG36: 5 | CH36: 5 | CI36: 4 | CJ36: 5 | CK36: 4 | CL36: 2 | CM36: 2 | CN36: 1
A37: P33 | B37: 9.7833333 | C37: 2 | D37: 2 | E37: 2 | O37: 10 | Q37: =COUNT(F37:P37) -> 1 | R37: =IF(Q37=1,MAX(F37:O37),11) -> 10 | AC37: 11 | AG37: =COUNT(S37:AE37) -> 1 | AR37: 1 | AZ37: 5 | BA37: 4 | BB37: 4 | BC37: 4 | BD37: 3 | BE37: 4 | BF37: 3 | BG37: 4 | BH37: 4 | BI37: 4 | BJ37: 5 | BK37: 5 | BL37: 4 | BM37: 4 | BN37: 2 | BO37: 3 | BP37: 3 | BQ37: 5 | BR37: 4 | BS37: 4 | BT37: 3 | BU37: 5 | BV37: 5 | BW37: 4 | BX37: 5 | BY37: 5 | BZ37: 4 | CA37: 4 | CB37: 5 | CC37: 5 | CD37: 4 | CE37: 3 | CF37: 4 | CG37: 4 | CH37: 4 | CI37: 4 | CJ37: 3 | CK37: 4 | CL37: 4 | CM37: 4 | CN37: 4
A38: P34 | B38: 10.216667 | C38: 2 | D38: 1 | E38: 8 | O38: 10 | Q38: =COUNT(F38:P38) -> 1 | R38: =IF(Q38=1,MAX(F38:O38),11) -> 10 | T38: 2 | X38: 6 | Y38: 7 | AB38: 10 | AG38: =COUNT(S38:AE38) -> 4 | AI38: 1 | AM38: 2 | AN38: 3 | AQ38: 4 | AU38: Be free grocer | AZ38: 4 | BA38: 5 | BB38: 4 | BC38: 5 | BD38: 4 | BE38: 5 | BF38: 3 | BG38: 4 | BH38: 3 | BI38: 4 | BJ38: 4 | BK38: 5 | BL38: 5 | BM38: 5 | BN38: 4 | BO38: 4 | BP38: 4 | BQ38: 4 | BR38: 5 | BS38: 4 | BT38: 3 | BU38: 4 | BV38: 2 | BW38: 5 | BX38: 5 | BY38: 4 | BZ38: 5 | CA38: 5 | CB38: 5 | CC38: 4 | CD38: 4 | CE38: 7 | CF38: 3 | CG38: 4 | CH38: 4 | CI38: 5 | CJ38: 4 | CK38: 5 | CL38: 4 | CM38: 4 | CN38: 3
A39: P35 | B39: 7.3666667 | C39: 2 | D39: 1 | E39: 13 | F39: 1 | Q39: =COUNT(F39:P39) -> 1 | R39: =IF(Q39=1,MAX(F39:O39),11) -> 1 | X39: 6 | Y39: 7 | AC39: 11 | AG39: =COUNT(S39:AE39) -> 3 | AM39: 2 | AN39: 1 | AR39: 3 | AU39: Wholesome culture | AZ39: 6 | BA39: 4 | BB39: 4 | BC39: 3 | BD39: 3 | BE39: 3 | BF39: 3 | BG39: 3 | BH39: 2 | BI39: 4 | BJ39: 4 | BK39: 5 | BL39: 5 | BM39: 5 | BN39: 4 | BO39: 3 | BP39: 3 | BQ39: 3 | BR39: 3 | BS39: 3 | BT39: 3 | BU39: 3 | BV39: 3 | BW39: 3 | BX39: 4 | BY39: 4 | BZ39: 4 | CA39: 5 | CB39: 4 | CC39: 4 | CD39: 3 | CE39: 1 | CF39: 4 | CG39: 4 | CH39: 4 | CI39: 3 | CJ39: 4 | CK39: 4 | CL39: 2 | CM39: 2 | CN39: 2
A40: P36 | B40: 11.9 | C40: 2 | D40: 5 | E40: 7 | F40: 1 | Q40: =COUNT(F40:P40) -> 1 | R40: =IF(Q40=1,MAX(F40:O40),11) -> 1 | T40: 2 | U40: 3 | Y40: 7 | AG40: =COUNT(S40:AE40) -> 3 | AI40: 1 | AJ40: 3 | AN40: 2 | AU40: Fonterra | AV40: Palmers | AZ40: 3 | BA40: 2 | BB40: 2 | BC40: 3 | BD40: 5 | BE40: 5 | BF40: 3 | BG40: 4 | BH40: 3 | BI40: 4 | BJ40: 4 | BK40: 5 | BL40: 5 | BM40: 5 | BN40: 4 | BO40: 4 | BP40: 4 | BQ40: 3 | BR40: 3 | BS40: 3 | BT40: 4 | BU40: 5 | BV40: 5 | BW40: 4 | BX40: 4 | BY40: 4 | BZ40: 4 | CA40: 4 | CB40: 3 | CC40: 3 | CD40: 4 | CE40: 2 | CF40: 4 | CG40: 4 | CH40: 3 | CI40: 3 | CJ40: 4 | CK40: 5 | CL40: 2 | CM40: 2 | CN40: 2
...

Sheet All Brand Mentions
A1: FirstMentions | B1: AllMentions
A2: Aa | B2: 1 Day
A3: Aa | B3: 2 degrees
A4: Aa | B4: 2Degrees
A5: Aa | B5: 2Degrees
A6: aa | B6: 99 bikes
A7: Adidas | B7: A1spice
A8: Adidas | B8: AA
A9: Afends | B9: Aa
A10: Air New Zealand | B10: Aa
A11: airnz | B11: Aa
A12: Alchemy equipment | B12: Aa
... A709: zoodoo | B709: genesis
B710: Genesis
B711: Genesis energy
B712: Genisis
B713: Girlfriend Collection
B714: Glad
B715: Glass production
B716: glassomns
B717: Glassons
B718: Glassons
B719: Glassons
B720: Global
B721: Glow lab
... B1730: Zuru
