Workbook

Sheet Lab1
A1: 115.109: Topic 1 Lab Worksheet
A2: Due date: August 3 | D2: Version: 1 (09.07)
A4: Task 1:
A5: This bike is a "classic seller" for the "classic rider". It last sold for RRP $439.99
E19: Answer | G19: Show Formula Used
A20: 1.1 | B20: What is the ex-GST price? | E20: =439.99/1.15 -> 382.6 | G20: =(439.99/1.15)
A21: 1.2 | B21: What is the GST included in the RRP? | E21: =((439.99 * 0.15) / 1.15) -> 57.39 | G21: =((439.99 * 0.15) / 1.15)
A23: If it costs $200 (ex-GST) to add the bike to inventory: | D23: COGS: | E23: 200
A24: 1.3 | B24: What is the Gross Margin $? (GM) | E24: =(E20 - E23) -> 182.6 | G24: =(E20 - E23)
A25: 1.4 | B25: What is the GM%? | E25: =((E24 / E20) * 100) -> 47.726085 | G25: =((E24 / E20) * 100)
A27: Recalculate 1.3-1.4 if the next purchase order raises the per unit acquisition cost (COGS) to $300 [formulas no longer required]
A28: 1.5 | B28: What is the COGS for the latest order? | E28: 300
A29: 1.6 | B29: What is the Gross Margin $? | E29: =(E20 - E28) -> 82.6
A30: 1.7 | B30: What is the Gross Margin %? | E30: =((E29 / E20) * 100) -> 21.589127
A31: 1.8 | B31: What is the markup %? | E31: =(E29/E28) * 100 -> 27.533333
A33: Task 2:
A34: A second model is added, a fully-suspended mountain e-bike.
A35: It has an RRP of $6999.99, but has a 20% 'launch' discount.
A47: Complete cells E52 to E61 based on the RRP, and G51:G61 based on the 20% discount.
A48: After weak sales, Torpedo7 then decide to further reduce the price to clear ("burn") the item, and price the bike at $5099.99 (including GST)
A49: Complete cells H52:H61 based on clearance ('burn') price.
E50: Full price: | G50: With 20% discount | H50: Clearance price:
D51: RRP: | E51: 6999.99 | G51: =(E51 * 0.8) -> 5599.992 | H51: 5099.99
A52: 2.1 | B52: What is the ex-GST price? | E52: =(E51/1.15) -> 6086.9478 | G52: =(E52 * 0.8) -> 4869.5583 | H52: =(H51 / 1.15) -> 4434.7739
B53: % discount for clearance | H53: =(H51-E51)/E51*100 -> -27.142896
A54: If it costs $4600 to add the bike to inventory: | D54: COGS | E54: 4600 | G54: 4600 | H54: 4600
A55: 2.2 | B55: What is the Gross Margin $? | E55: =( E52 - E54) -> 1486.9478 | G55: =( G52 - G54) -> 269.55826 | H55: =( H52 - H54) -> -165.22609
A56: 2.3 | B56: What is the GM%? | E56: =(E55 / E52) * 100 -> 24.428463 | G56: =(G55 / G52) * 100 -> 5.5355793 | H56: =( H55 / H52 ) * 100 -> -3.7256936
A58: Units sold at that RRP: | E58: 10 | G58: 20 | H58: 30
A59: 2.4 | B59: What is the total sales revenue? (ex-GST) | E59: =(E52 * E58) -> 60869.478 | G59: =(G52 *G58) -> 97391.165 | H59: =(H52 * H58) -> 133043.22
A60: 2.5 | B60: What is the total gross margin $? | E60: =(E55*E58) -> 14869.478 | G60: =(G55 * G58) -> 5391.1652 | H60: =(H55 * H58) -> -4956.7826
A61: 2.6 | C61: and %? | E61: =(E55 / E52 ) * 100 -> 24.428463 | G61: =(G55 / G52 ) * 100 -> 5.5355793 | H61: =(H55 / H52 ) * 100 -> -3.7256936
A62: 2.7 | B62: Was the discount worthwhile in profit terms?
A66: Task 3: Using the "SustainabilityData-10%sample" datasheet, do some data checks
A67: This is an ~10% subsample: a selection from a larger dataset, which we will use in future labs (and in the report).
A68: For now, we need to check all data is OK (no missing data), and transform column B
A69: Process:
A70: 1) Do the following in the SustainabilityData-10%sample tab at the bottom of the spreadsheet
A71: 2) Use the quick scrolling keys to go the bottom and right of the dataset: holding the Cntrl key (Windows) or Command key (Mac) and press the down arrow key to go the bottom of an 'array' (contiguous set of data)
A72: Hold the Cntrl / Command key (Windows/Mac) and press the right arrow key to go the far right of an 'array' (contiguous set of data).
...

Sheet Lab2
A1: 115.109: Topic 2 Lab Worksheet | E1: Your Name: | F1: Savnit Prasad
A2: ='Lab1'!A2 -> Due date: August 3 | C2: ='Lab1'!D2 -> Version: 1 (09.07) | E2: Student ID: | F2: 26019118
A4: Task 1:
A5: Locate the The Warehouse Group 2024 and 2025 Income Statements: extracts available in Week 1 lecture notes
A6: Links to financial statements:
A7: 2025 Annual Report financial statement: | B7: https://www.thewarehousegroup.co.nz/download_file/force/83c5e7a5-091c-45a0-8371-f47056936994/174 | G7: p. 36
A8: 2024 Annual Report financial statement: | B8: https://www.thewarehousegroup.co.nz/download_file/force/5a624589-60db-46c4-ae0a-c630e68b01eb/174 | G8: p. 44 | H8: (includes 2023 info: both 52 week periods)
A10: Complete the following table:
A11: Financial Year ending July | B11: (Income statements reported in $000s - paste into the formula bar not the actual cell, to retain formatting.)
B12: 2025 | C12: 2024 | E12: Var | F12: % var | G12: 2023 | I12: Var | J12: % var
C13: (restated in 2024: use the values from 2024 report)
A14: Sales (Total Revenue) | B14: 3086725 | C14: 3037597 | D14: =F14 -> 0.016173311 | E14: =B14-C14 -> 49128 | F14: =E14/C14 -> 0.016173311 | G14: 3236912 | H14: =J14 -> -0.061575662 | I14: =C14-G14 -> -199315 | J14: =I14/G14 -> -0.061575662
A15: COGS (Cost of Retail Goods Sold) | B15: 2091643 | C15: 2016731 | D15: =F15 -> -0.037145261 | E15: =-(B15-C15) -> -74912 | F15: =-(B15-C15)/C15 -> -0.037145261 | G15: 2148681 | H15: =J15 -> 0.061409767 | I15: =-(C15-G15) -> 131950 | J15: =I15/G15 -> 0.061409767
A16: COGS % sales revenue | B16: =B15/B14 -> 0.67762531 | C16: =C15/C14 -> 0.66392316 | D16: =F16 -> -0.013702155 | E16: =-(B16-C16) -> -0.013702155 | F16: =-(B16-C16) -> -0.013702155 | G16: =G15/G14 -> 0.66380581 | H16: =J16 -> -0.00011734786 | I16: =-(C16-G16) -> -0.00011734786 | J16: =I16 -> -0.00011734786
A17: Gross Profit $ | B17: =B14-B15 -> 995082 | C17: =C14-C15 -> 1020866 | D17: =F17 -> -0.025256988 | E17: =B17-C17 -> -25784 | F17: =(B17-C17)/C17 -> -0.025256988 | G17: =G14-G15 -> 1088231 | H17: =J17 -> -0.061903217 | I17: =C17-G17 -> -67365 | J17: =I17/G17 -> -0.061903217
A18: GP % sales revenue | B18: =B17/B14 -> 0.32237469 | C18: =C17/C14 -> 0.33607684 | D18: =F18 -> -0.013702155 | E18: =B18-C18 -> -0.013702155 | F18: =B18-C18 -> -0.013702155 | G18: =G17/G14 -> 0.33619419 | H18: =J18 -> -0.00011734786 | I18: =C18-G18 -> -0.00011734786 | J18: =I18 -> -0.00011734786
A19: CODB (Lease, Employee, Depreciation,Other expense) | B19: =526520 + 156524 + 285836 -> 968880 | C19: =512146 + 158558 +290284 -> 960988 | D19: =F19 -> -0.0082123814 | E19: =-(B19-C19) -> -7892 | F19: =-(B19-C19)/C19 -> -0.0082123814 | G19: =535770 + 151891 + 286615 -> 974276 | H19: =J19 -> 0.013638846 | I19: =-(C19-G19) -> 13288 | J19: =I19/G19 -> 0.013638846
A20: CODB % sales revenue | B20: =B19/B14 -> 0.31388608 | C20: =C19/C14 -> 0.31636455 | D20: =F20 -> 0.0024784707 | E20: =-(B20-C20) -> 0.0024784707 | F20: =-(B20-C20) -> 0.0024784707 | G20: =G19/G14 -> 0.30098934 | H20: =J20 -> -0.015375209 | I20: =-(C20-G20) -> -0.015375209 | J20: =I20 -> -0.015375209
A21: EBIT (Earnings before Interest and Tax) from retail operations | B21: =B17-B19 -> 26202 | C21: =C17-C19 -> 59878 | D21: =F21 -> -0.56241023 | E21: =B21-C21 -> -33676 | F21: =(B21-C21)/C21 -> -0.56241023 | G21: =G17-G19 -> 113955 | H21: =J21 -> -0.47454697 | I21: =C21-G21 -> -54077 | J21: =I21/G21 -> -0.47454697
A22: EBIT % sales revenue | B22: =B21/B14 -> 0.0084886085 | C22: =C21/C14 -> 0.019712292 | D22: =F22 -> -0.011223684 | E22: =B22-C22 -> -0.011223684 | F22: =B22-C22 -> -0.011223684 | G22: =G21/G14 -> 0.03520485 | H22: =J22 -> -0.015492557 | I22: =C22-G22 -> -0.015492557 | J22: =I22 -> -0.015492557
A24: Interpret the table: what improved, and did not, between 2023-2024, and 2024-2025? | E24: {you can resize this box if you want}
A29: Task 2: Analyse sustainability knowledge (SustainabilityData-10%sample)
A30: 1) The CountIf function used in Lab1 used a fixed criterion to determine what to count in a specified range of data (eg 2 or 3). The criterion can also refer to a cell, and so can vary.
A31: Use the following table to determine the frequencies of each response level for the two 'Subjective Knowledge' questions (columns AI, AJ and AK in the SustainabilityData sheet)
A32: 2) In cell C38 of this sheet, enter the formula: =COUNTIF('SustainabilityData-10%sample'!AI$5:AI$108,$B38) [you can copy this, and paste into the formula bar for that cell]
A33: (We use a $ in front of the numbers so the specified range stays the same when you copy formula down the next six rows;
A34: AND in front of the letter B so that the criterion stays the same when you copy across to columns D and E)
A35: 3) Now copy cell C38, and Paste Special > Formulas into C38:E42 (select the whole range when Pasting Special) [dragging will overwrite the green and red box formatting, so don't do that!]
B37: Response level | C37: Column AI: "I have a good knowledge about sustainability issues" | D37: Column AJ: "I know a great deal about sustainability and sustainability matters" | E37: Column AK: "I know a lot about sustainable products and brands sold in the marketplace" | F37: % of respondents in column AI | G37: % of respondents in column AJ | H37: % of respondents in column AK
B38: 1 | C38: =COUNTIF('SustainabilityData-10%sample'!AI$5:AI$108,$B38) -> 5 | D38: =COUNTIF('SustainabilityData-10%sample'!AJ$5:AJ$108,$B38) -> 7 | E38: =COUNTIF('SustainabilityData-10%sample'!AK$5:AK$108,$B38) -> 11 | F38: =C38/C$43*100 -> 4.8076923 | G38: =D38/D$43*100 -> 6.7307692 | H38: =E38/E$43*100 -> 10.576923
B39: 2 | C39: =COUNTIF('SustainabilityData-10%sample'!AI$5:AI$108,$B39) -> 22 | D39: =COUNTIF('SustainabilityData-10%sample'!AJ$5:AJ$108,$B39) -> 24 | E39: =COUNTIF('SustainabilityData-10%sample'!AK$5:AK$108,$B39) -> 27 | F39: =C39/C$43*100 -> 21.153846 | G39: =D39/D$43*100 -> 23.076923 | H39: =E39/E$43*100 -> 25.961538
B40: 3 | C40: =COUNTIF('SustainabilityData-10%sample'!AI$5:AI$108,$B40) -> 32 | D40: =COUNTIF('SustainabilityData-10%sample'!AJ$5:AJ$108,$B40) -> 33 | E40: =COUNTIF('SustainabilityData-10%sample'!AK$5:AK$108,$B40) -> 30 | F40: =C40/C$43*100 -> 30.769231 | G40: =D40/D$43*100 -> 31.730769 | H40: =E40/E$43*100 -> 28.846154
B41: 4 | C41: =COUNTIF('SustainabilityData-10%sample'!AI$5:AI$108,$B41) -> 36 | D41: =COUNTIF('SustainabilityData-10%sample'!AJ$5:AJ$108,$B41) -> 32 | E41: =COUNTIF('SustainabilityData-10%sample'!AK$5:AK$108,$B41) -> 31 | F41: =C41/C$43*100 -> 34.615385 | G41: =D41/D$43*100 -> 30.769231 | H41: =E41/E$43*100 -> 29.807692
B42: 5 | C42: =COUNTIF('SustainabilityData-10%sample'!AI$5:AI$108,$B42) -> 9 | D42: =COUNTIF('SustainabilityData-10%sample'!AJ$5:AJ$108,$B42) -> 8 | E42: =COUNTIF('SustainabilityData-10%sample'!AK$5:AK$108,$B42) -> 5 | F42: =C42/C$43*100 -> 8.6538462 | G42: =D42/D$43*100 -> 7.6923077 | H42: =E42/E$43*100 -> 4.8076923
B43: Total | C43: =SUM(C38:C42) -> 104 | D43: =SUM(D38:D42) -> 104 | E43: =SUM(E38:E42) -> 104
A45: Task 3: Contrast subjective knowledge of sustainability
A46: 1) Calculate the % of total respondents in cells C38:C42 above. For cell F38, enter the formula =C38/C$43*100
A47: 2) What would happen if you copy that formula into cell E39 WITHOUT that dollar sign? (see hint in row 33 above)
A48: 3) Do the equivalent calculations for G38:H42
A49: 4) How knowledgeable do respondents claim to be?
...

Sheet SustainabilityData-10%sample
A1: Variable Group | G1: What does sustainability mean to you? (select all that apply) | V1: Sustainable intentions and behaiour | AC1: Sustainability literacy
A2: Variable | B2: Survey Duration (text) | D2: Duration (min) | E2: Gender | F2: Age | G2: Corporate citizenship | H2: Enviro responsible | I2: Zero waste | J2: Social responsible | K2: Carbon emissions | L2: Renewables | M2: Ecosystems | N2: Climate change | O2: Social well-being | P2: Traceability | Q2: Water | R2: Waterways | S2: Limiting growth | T2: Not sure | U2: Number of Items picked | V2: HowOftenBuy | W2: LikelyPayMore | X2: WillingPayMore | Y2: AcceptablePayMore | Z2: Return Packaging | AA2: Bottle Deposit scheme | AB2: Household Income | AC2: Capable to solve | AD2: Contribute | AE2: Can help | AF2: Purchase effect | AG2: Positive effect | AH2: Individual difference | AI2: Good knowledge | AJ2: Know sustainability | AK2: Know sustainable brands
A3: Question | B3: Elapsed time to complete survey | D3: Calculation based on elapsed time | E3: Which gender do you identify with? | F3: Which of the following age groups do you fit into:Â | G3: Good corporate citizenship | H3: Being environmentally responsible | I3: Targeting zero waste | J3: Being socially responsible | K3: Carbon emission reduction | L3: Using renewable resources | M3: Protecting ecosystems | N3: Having actionable plans for climate change | O3: Having social well-being focus rather than economic progress | P3: Traceability (can trace where the product has come from "farm to fork") | Q3: Conserving water | R3: Cleaning our waterways and oceans | S3: Limiting population and economic growth | U3: Items Picked | V3: How often do you buy a product that has come from a business that implements sustainable practices? | W3: How likely are you to pay more for a product that has come from a business that implements sustainable practices? | X3: I am willing to spend more money in order to buy products that are sustainable | Y3: I believe it is acceptable to spend extra money for products that are sustainable | Z3: Retailers should be required to take back packaging they sell product in (including cardboard, bubble, wrap or filler, polystyrene.. | AA3: There should be a bottle deposit scheme, with customers reimbursed for taking back milk, juice and water bottles to the retailer or a recycle station | AB3: What is your total household income before tax?Â | AC3: I feel capable of helping solve sustainability issues, e.g. environment, societal problems | AD3: I can contribute to a sustainable future by buying products that are made sustainably | AE3: I feel I can help solve sustainability issues by buying sustainable products | AF3: What I purchase as a consumer has an effect on the nation’s future sustainability | AG3: Each consumer’s behaviour can have a positive effect on society by buying products that are sustainable | AH3: Any individual person can make a difference to the world by choosing products carefully | AI3: I have a good knowledge about sustainability issues | AJ3: I know a great deal about sustainability and sustainability matters | AK3: I know a lot about sustainable products and brands sold in the marketplace
A4: Variable coding: Response Respondent: | B4: Note: To completely answer the full survey a respondent would take a minimum of 240 seconds. 2: New Zealand 3: United States | D4: Minutes | E4: 1: Male 2: Female 3: Gender diverse | F4: 7: Under 18 1: 18-24 2: 25-34 3: 35-44 4: 45-54 5: 55-64 6: 65+ | G4: These numbers don't mean anything per se (nominal data), just that the item was chosen. You can count how many times each item was chosen individually, but analysing combinations within multi-pick questions is problematic! | V4: 1: Not at all 5: Very often 6: Don't know | W4: 1: Not likely 5: Very likely | X4: 1: Strongly disagree 3: Neither disagree nor agree 5: Strongly agree | Y4: 1: Strongly disagree 3: Neither disagree nor agree 5: Strongly agree | Z4: 1: Strongly disagree 3: Neither disagree nor agree 5: Strongly agree | AA4: 1: Strongly disagree 3: Neither disagree nor agree 5: Strongly agree | AB4: 1: Up to $30,000 2: $30,001 - $50,000 3: $50,001 - $70,000 4: $70,001 - $100,000 5: $100,001 - $130,000 6: Over $130,000 7: Would rather not say | AC4: 1: Strongly disagree 3: Neither disagree nor agree 5: Strongly agree | AD4: 1: Strongly disagree 3: Neither disagree nor agree 5: Strongly agree | AE4: 1: Strongly disagree 3: Neither disagree nor agree 5: Strongly agree | AF4: 1: Strongly disagree 3: Neither disagree nor agree 5: Strongly agree | AG4: 1: Strongly disagree 3: Neither disagree nor agree 5: Strongly agree | AH4: 1: Strongly disagree 3: Neither disagree nor agree 5: Strongly agree | AI4: 1: Strongly disagree 3: Neither disagree nor agree 5: Strongly agree | AJ4: 1: Strongly disagree 3: Neither disagree nor agree 5: Strongly agree | AK4: 1: Strongly disagree 3: Neither disagree nor agree 5: Strongly agree
A5: P80 | B5: 14667 | C5: sec | D5: =B5/60 -> 244.45 | E5: 2 | F5: 2 | H5: 2 | J5: 4 | M5: 7 | U5: =COUNT(G5:S5) -> 3 | V5: 3 | W5: 3 | X5: 4 | Y5: 4 | Z5: 3 | AA5: 3 | AB5: 2 | AC5: 3 | AD5: 4 | AE5: 3 | AF5: 3 | AG5: 3 | AH5: 4 | AI5: 3 | AJ5: 3 | AK5: 2
A6: P98 | B6: 4705 | C6: sec | D6: =B6/60 -> 78.416667 | E6: 1 | F6: 3 | I6: 3 | K6: 5 | L6: 6 | M6: 7 | N6: 8 | R6: 12 | S6: 13 | U6: =COUNT(G6:S6) -> 7 | V6: 4 | W6: 3 | X6: 3 | Y6: 3 | Z6: 3 | AA6: 3 | AB6: 7 | AC6: 3 | AD6: 3 | AE6: 3 | AF6: 3 | AG6: 3 | AH6: 3 | AI6: 3 | AJ6: 3 | AK6: 3
A7: P102 | B7: 4705 | C7: sec | D7: =B7/60 -> 78.416667 | E7: 2 | F7: 2 | J7: 4 | L7: 6 | O7: 9 | R7: 12 | U7: =COUNT(G7:S7) -> 4 | V7: 4 | W7: 4 | X7: 2 | Y7: 3 | Z7: 3 | AA7: 4 | AB7: 4 | AC7: 4 | AD7: 3 | AE7: 4 | AF7: 5 | AG7: 4 | AH7: 4 | AI7: 4 | AJ7: 3 | AK7: 4
A8: P42 | B8: 2553 | C8: sec | D8: =B8/60 -> 42.55 | E8: 2 | F8: 5 | H8: 2 | I8: 3 | J8: 4 | L8: 6 | M8: 7 | N8: 8 | O8: 9 | P8: 10 | Q8: 11 | R8: 12 | U8: =COUNT(G8:S8) -> 10 | V8: 6 | W8: 3 | X8: 2 | Y8: 3 | Z8: 5 | AA8: 5 | AB8: 2 | AC8: 3 | AD8: 4 | AE8: 5 | AF8: 4 | AG8: 5 | AH8: 5 | AI8: 2 | AJ8: 2 | AK8: 1
A9: P67 | B9: 2127 | C9: sec | D9: =B9/60 -> 35.45 | E9: 2 | F9: 1 | H9: 2 | I9: 3 | J9: 4 | K9: 5 | L9: 6 | M9: 7 | N9: 8 | Q9: 11 | R9: 12 | S9: 13 | U9: =COUNT(G9:S9) -> 10 | V9: 4 | W9: 4 | X9: 3 | Y9: 3 | Z9: 5 | AA9: 3 | AB9: 2 | AC9: 4 | AD9: 5 | AE9: 4 | AF9: 5 | AG9: 5 | AH9: 5 | AI9: 3 | AJ9: 3 | AK9: 3
A10: P2 | B10: 1861 | C10: sec | D10: =B10/60 -> 31.016667 | E10: 2 | F10: 5 | H10: 2 | I10: 3 | K10: 5 | L10: 6 | N10: 8 | P10: 10 | R10: 12 | U10: =COUNT(G10:S10) -> 7 | V10: 6 | W10: 3 | X10: 3 | Y10: 4 | Z10: 4 | AA10: 4 | AB10: 1 | AC10: 3 | AD10: 4 | AE10: 3 | AF10: 4 | AG10: 4 | AH10: 4 | AI10: 2 | AJ10: 1 | AK10: 2
A11: P40 | B11: 1790 | C11: sec | D11: =B11/60 -> 29.833333 | E11: 2 | F11: 2 | H11: 2 | U11: =COUNT(G11:S11) -> 1 | V11: 5 | W11: 5 | X11: 5 | Y11: 5 | Z11: 5 | AA11: 5 | AB11: 3 | AC11: 5 | AD11: 5 | AE11: 5 | AF11: 5 | AG11: 5 | AH11: 5 | AI11: 5 | AJ11: 5 | AK11: 5
A12: P91 | B12: 1768 | C12: sec | D12: =B12/60 -> 29.466667 | E12: 2 | F12: 3 | H12: 2 | I12: 3 | L12: 6 | M12: 7 | Q12: 11 | U12: =COUNT(G12:S12) -> 5 | V12: 1 | W12: 2 | X12: 2 | Y12: 3 | Z12: 5 | AA12: 5 | AB12: 4 | AC12: 3 | AD12: 3 | AE12: 3 | AF12: 2 | AG12: 3 | AH12: 3 | AI12: 3 | AJ12: 3 | AK12: 2
A13: P59 | B13: 1639 | C13: sec | D13: =B13/60 -> 27.316667 | E13: 2 | F13: 2 | H13: 2 | I13: 3 | K13: 5 | L13: 6 | M13: 7 | P13: 10 | Q13: 11 | R13: 12 | U13: =COUNT(G13:S13) -> 8 | V13: 2 | W13: 4 | X13: 3 | Y13: 4 | Z13: 4 | AA13: 5 | AB13: 3 | AC13: 2 | AD13: 5 | AE13: 5 | AF13: 4 | AG13: 5 | AH13: 5 | AI13: 4 | AJ13: 3 | AK13: 3
A14: P73 | B14: 1636 | C14: sec | D14: =B14/60 -> 27.266667 | E14: 2 | F14: 4 | G14: 1 | H14: 2 | I14: 3 | J14: 4 | K14: 5 | L14: 6 | M14: 7 | N14: 8 | O14: 9 | P14: 10 | Q14: 11 | R14: 12 | S14: 13 | U14: =COUNT(G14:S14) -> 13 | V14: 6 | W14: 5 | X14: 5 | Y14: 5 | Z14: 5 | AA14: 5 | AB14: 2 | AC14: 4 | AD14: 5 | AE14: 4 | AF14: 5 | AG14: 5 | AH14: 5 | AI14: 3 | AJ14: 3 | AK14: 3
A15: P94 | B15: 1582 | C15: sec | D15: =B15/60 -> 26.366667 | E15: 1 | F15: 3 | G15: 1 | J15: 4 | M15: 7 | Q15: 11 | U15: =COUNT(G15:S15) -> 4 | V15: 5 | W15: 5 | X15: 5 | Y15: 5 | Z15: 4 | AA15: 5 | AB15: 1 | AC15: 5 | AD15: 5 | AE15: 5 | AF15: 4 | AG15: 5 | AH15: 5 | AI15: 5 | AJ15: 4 | AK15: 5
A16: P48 | B16: 1572 | C16: sec | D16: =B16/60 -> 26.2 | E16: 2 | F16: 2 | I16: 3 | J16: 4 | K16: 5 | L16: 6 | M16: 7 | P16: 10 | Q16: 11 | R16: 12 | U16: =COUNT(G16:S16) -> 8 | V16: 3 | W16: 4 | X16: 4 | Y16: 4 | Z16: 4 | AA16: 4 | AB16: 5 | AC16: 4 | AD16: 5 | AE16: 5 | AF16: 5 | AG16: 4 | AH16: 4 | AI16: 4 | AJ16: 4 | AK16: 4
A17: P79 | B17: 1506 | C17: sec | D17: =B17/60 -> 25.1 | E17: 2 | F17: 6 | H17: 2 | I17: 3 | K17: 5 | L17: 6 | M17: 7 | N17: 8 | P17: 10 | Q17: 11 | R17: 12 | S17: 13 | U17: =COUNT(G17:S17) -> 10 | V17: 4 | W17: 4 | X17: 4 | Y17: 4 | Z17: 5 | AA17: 5 | AB17: 4 | AC17: 5 | AD17: 5 | AE17: 5 | AF17: 5 | AG17: 3 | AH17: 5 | AI17: 4 | AJ17: 4 | AK17: 4
A18: P54 | B18: 1353 | C18: sec | D18: =B18/60 -> 22.55 | E18: 1 | F18: 2 | H18: 2 | J18: 4 | K18: 5 | L18: 6 | N18: 8 | O18: 9 | P18: 10 | Q18: 11 | R18: 12 | U18: =COUNT(G18:S18) -> 9 | V18: 3 | W18: 1 | X18: 5 | Y18: 1 | Z18: 5 | AA18: 5 | AB18: 3 | AC18: 5 | AD18: 5 | AE18: 1 | AF18: 3 | AG18: 2 | AH18: 1 | AI18: 2 | AJ18: 3 | AK18: 1
A19: P38 | B19: 1316 | C19: sec | D19: =B19/60 -> 21.933333 | E19: 2 | F19: 6 | H19: 2 | I19: 3 | J19: 4 | K19: 5 | L19: 6 | M19: 7 | P19: 10 | Q19: 11 | R19: 12 | U19: =COUNT(G19:S19) -> 9 | V19: 6 | W19: 3 | X19: 3 | Y19: 3 | Z19: 4 | AA19: 5 | AB19: 2 | AC19: 3 | AD19: 3 | AE19: 3 | AF19: 4 | AG19: 4 | AH19: 3 | AI19: 3 | AJ19: 3 | AK19: 3
A20: P65 | B20: 1168 | C20: sec | D20: =B20/60 -> 19.466667 | E20: 2 | F20: 2 | H20: 2 | I20: 3 | K20: 5 | L20: 6 | M20: 7 | N20: 8 | Q20: 11 | R20: 12 | U20: =COUNT(G20:S20) -> 8 | V20: 2 | W20: 2 | X20: 3 | Y20: 3 | Z20: 5 | AA20: 5 | AB20: 5 | AC20: 3 | AD20: 4 | AE20: 3 | AF20: 5 | AG20: 4 | AH20: 4 | AI20: 2 | AJ20: 2 | AK20: 1
A21: P83 | B21: 1155 | C21: sec | D21: =B21/60 -> 19.25 | E21: 2 | F21: 1 | H21: 2 | I21: 3 | K21: 5 | L21: 6 | M21: 7 | N21: 8 | Q21: 11 | R21: 12 | U21: =COUNT(G21:S21) -> 8 | V21: 4 | W21: 4 | X21: 4 | Y21: 4 | Z21: 2 | AA21: 5 | AB21: 4 | AC21: 4 | AD21: 4 | AE21: 4 | AF21: 4 | AG21: 4 | AH21: 4 | AI21: 5 | AJ21: 5 | AK21: 4
A22: P69 | B22: 1126 | C22: sec | D22: =B22/60 -> 18.766667 | E22: 2 | F22: 6 | H22: 2 | I22: 3 | J22: 4 | K22: 5 | L22: 6 | M22: 7 | N22: 8 | P22: 10 | Q22: 11 | R22: 12 | S22: 13 | U22: =COUNT(G22:S22) -> 11 | V22: 6 | W22: 3 | X22: 3 | Y22: 4 | Z22: 3 | AA22: 5 | AB22: 2 | AC22: 5 | AD22: 5 | AE22: 5 | AF22: 5 | AG22: 5 | AH22: 5 | AI22: 4 | AJ22: 4 | AK22: 3
A23: P17 | B23: 1074 | C23: sec | D23: =B23/60 -> 17.9 | E23: 2 | F23: 6 | G23: 1 | H23: 2 | I23: 3 | J23: 4 | K23: 5 | L23: 6 | P23: 10 | Q23: 11 | R23: 12 | U23: =COUNT(G23:S23) -> 9 | V23: 5 | W23: 4 | X23: 4 | Y23: 4 | Z23: 5 | AA23: 5 | AB23: 2 | AC23: 5 | AD23: 5 | AE23: 5 | AF23: 5 | AG23: 5 | AH23: 5 | AI23: 3 | AJ23: 3 | AK23: 3
A24: P18 | B24: 1019 | C24: sec | D24: =B24/60 -> 16.983333 | E24: 2 | F24: 2 | H24: 2 | I24: 3 | K24: 5 | L24: 6 | N24: 8 | U24: =COUNT(G24:S24) -> 5 | V24: 3 | W24: 2 | X24: 3 | Y24: 3 | Z24: 3 | AA24: 3 | AB24: 7 | AC24: 4 | AD24: 3 | AE24: 4 | AF24: 3 | AG24: 1 | AH24: 5 | AI24: 2 | AJ24: 3 | AK24: 2
A25: P15 | B25: 999 | C25: sec | D25: =B25/60 -> 16.65 | E25: 2 | F25: 1 | H25: 2 | I25: 3 | J25: 4 | M25: 7 | O25: 9 | S25: 13 | U25: =COUNT(G25:S25) -> 6 | V25: 3 | W25: 4 | X25: 4 | Y25: 4 | Z25: 3 | AA25: 5 | AB25: 3 | AC25: 5 | AD25: 5 | AE25: 4 | AF25: 5 | AG25: 5 | AH25: 5 | AI25: 3 | AJ25: 2 | AK25: 2
A26: P31 | B26: 970 | C26: sec | D26: =B26/60 -> 16.166667 | E26: 1 | F26: 2 | H26: 2 | K26: 5 | L26: 6 | M26: 7 | N26: 8 | Q26: 11 | U26: =COUNT(G26:S26) -> 6 | V26: 6 | W26: 1 | X26: 1 | Y26: 1 | Z26: 5 | AA26: 5 | AB26: 7 | AC26: 5 | AD26: 5 | AE26: 5 | AF26: 5 | AG26: 5 | AH26: 5 | AI26: 3 | AJ26: 2 | AK26: 2
A27: P11 | B27: 956 | C27: sec | D27: =B27/60 -> 15.933333 | E27: 1 | F27: 2 | G27: 1 | H27: 2 | J27: 4 | L27: 6 | O27: 9 | P27: 10 | U27: =COUNT(G27:S27) -> 6 | V27: 4 | W27: 4 | X27: 4 | Y27: 4 | Z27: 5 | AA27: 2 | AB27: 6 | AC27: 4 | AD27: 3 | AE27: 2 | AF27: 5 | AG27: 2 | AH27: 4 | AI27: 4 | AJ27: 5 | AK27: 5
A28: P8 | B28: 952 | C28: sec | D28: =B28/60 -> 15.866667 | E28: 2 | F28: 2 | H28: 2 | J28: 4 | K28: 5 | L28: 6 | M28: 7 | U28: =COUNT(G28:S28) -> 5 | V28: 4 | W28: 4 | X28: 4 | Y28: 3 | Z28: 5 | AA28: 4 | AB28: 7 | AC28: 4 | AD28: 4 | AE28: 4 | AF28: 4 | AG28: 4 | AH28: 4 | AI28: 4 | AJ28: 4 | AK28: 4
A29: P41 | B29: 940 | C29: sec | D29: =B29/60 -> 15.666667 | E29: 2 | F29: 2 | H29: 2 | J29: 4 | L29: 6 | M29: 7 | O29: 9 | U29: =COUNT(G29:S29) -> 5 | V29: 4 | W29: 4 | X29: 4 | Y29: 3 | Z29: 3 | AA29: 5 | AB29: 7 | AC29: 3 | AD29: 5 | AE29: 5 | AF29: 4 | AG29: 5 | AH29: 4 | AI29: 3 | AJ29: 3 | AK29: 3
A30: P93 | B30: 934 | C30: sec | D30: =B30/60 -> 15.566667 | E30: 1 | F30: 2 | Q30: 11 | U30: =COUNT(G30:S30) -> 1 | V30: 4 | W30: 3 | X30: 3 | Y30: 3 | Z30: 3 | AA30: 3 | AB30: 4 | AC30: 3 | AD30: 3 | AE30: 3 | AF30: 3 | AG30: 3 | AH30: 3 | AI30: 3 | AJ30: 3 | AK30: 3
A31: P78 | B31: 920 | C31: sec | D31: =B31/60 -> 15.333333 | E31: 2 | F31: 1 | H31: 2 | I31: 3 | K31: 5 | L31: 6 | M31: 7 | N31: 8 | Q31: 11 | U31: =COUNT(G31:S31) -> 7 | V31: 4 | W31: 4 | X31: 4 | Y31: 5 | Z31: 4 | AA31: 4 | AB31: 3 | AC31: 3 | AD31: 4 | AE31: 4 | AF31: 5 | AG31: 4 | AH31: 4 | AI31: 4 | AJ31: 4 | AK31: 4
A32: P14 | B32: 883 | C32: sec | D32: =B32/60 -> 14.716667 | E32: 1 | F32: 1 | H32: 2 | N32: 8 | U32: =COUNT(G32:S32) -> 2 | V32: 2 | W32: 3 | X32: 3 | Y32: 3 | Z32: 4 | AA32: 5 | AB32: 3 | AC32: 3 | AD32: 3 | AE32: 3 | AF32: 3 | AG32: 3 | AH32: 4 | AI32: 4 | AJ32: 3 | AK32: 2
A33: P51 | B33: 878 | C33: sec | D33: =B33/60 -> 14.633333 | E33: 2 | F33: 6 | H33: 2 | L33: 6 | U33: =COUNT(G33:S33) -> 2 | V33: 6 | W33: 3 | X33: 3 | Y33: 3 | Z33: 3 | AA33: 4 | AB33: 6 | AC33: 2 | AD33: 3 | AE33: 4 | AF33: 3 | AG33: 4 | AH33: 3 | AI33: 1 | AJ33: 1 | AK33: 1
A34: P77 | B34: 876 | C34: sec | D34: =B34/60 -> 14.6 | E34: 2 | F34: 6 | G34: 1 | J34: 4 | U34: =COUNT(G34:S34) -> 2 | V34: 5 | W34: 3 | X34: 3 | Y34: 3 | Z34: 3 | AA34: 4 | AB34: 1 | AC34: 3 | AD34: 3 | AE34: 3 | AF34: 3 | AG34: 3 | AH34: 4 | AI34: 2 | AJ34: 2 | AK34: 2
A35: P24 | B35: 864 | C35: sec | D35: =B35/60 -> 14.4 | E35: 1 | F35: 5 | G35: 1 | U35: =COUNT(G35:S35) -> 1 | V35: 5 | W35: 4 | X35: 4 | Y35: 4 | Z35: 3 | AA35: 4 | AB35: 4 | AC35: 4 | AD35: 5 | AE35: 4 | AF35: 4 | AG35: 4 | AH35: 4 | AI35: 4 | AJ35: 4 | AK35: 4
A36: P57 | B36: 824 | C36: sec | D36: =B36/60 -> 13.733333 | E36: 2 | F36: 2 | H36: 2 | I36: 3 | K36: 5 | L36: 6 | M36: 7 | N36: 8 | R36: 12 | U36: =COUNT(G36:S36) -> 7 | V36: 3 | W36: 3 | X36: 3 | Y36: 3 | Z36: 4 | AA36: 5 | AB36: 7 | AC36: 4 | AD36: 4 | AE36: 3 | AF36: 4 | AG36: 4 | AH36: 4 | AI36: 4 | AJ36: 4 | AK36: 4
A37: P3 | B37: 821 | C37: sec | D37: =B37/60 -> 13.683333 | E37: 2 | F37: 4 | H37: 2 | M37: 7 | N37: 8 | Q37: 11 | R37: 12 | U37: =COUNT(G37:S37) -> 5 | V37: 4 | W37: 5 | X37: 5 | Y37: 5 | Z37: 5 | AA37: 5 | AB37: 1 | AC37: 5 | AD37: 5 | AE37: 5 | AF37: 5 | AG37: 5 | AH37: 5 | AI37: 3 | AJ37: 3 | AK37: 3
A38: P21 | B38: 821 | C38: sec | D38: =B38/60 -> 13.683333 | E38: 2 | F38: 2 | H38: 2 | I38: 3 | J38: 4 | L38: 6 | N38: 8 | P38: 10 | U38: =COUNT(G38:S38) -> 6 | V38: 4 | W38: 4 | X38: 4 | Y38: 4 | Z38: 4 | AA38: 4 | AB38: 5 | AC38: 3 | AD38: 4 | AE38: 3 | AF38: 3 | AG38: 4 | AH38: 4 | AI38: 3 | AJ38: 3 | AK38: 3
A39: P53 | B39: 800 | C39: sec | D39: =B39/60 -> 13.333333 | E39: 2 | F39: 2 | H39: 2 | J39: 4 | L39: 6 | M39: 7 | N39: 8 | O39: 9 | U39: =COUNT(G39:S39) -> 6 | V39: 6 | W39: 4 | X39: 3 | Y39: 4 | Z39: 5 | AA39: 4 | AB39: 2 | AC39: 2 | AD39: 3 | AE39: 2 | AF39: 3 | AG39: 3 | AH39: 3 | AI39: 3 | AJ39: 4 | AK39: 3
A40: P82 | B40: 786 | C40: sec | D40: =B40/60 -> 13.1 | E40: 2 | F40: 2 | T40: 14 | U40: =COUNT(G40:S40) -> 0 | V40: 4 | W40: 3 | X40: 2 | Y40: 2 | Z40: 2 | AA40: 4 | AB40: 3 | AC40: 2 | AD40: 4 | AE40: 3 | AF40: 4 | AG40: 3 | AH40: 4 | AI40: 2 | AJ40: 1 | AK40: 2
...
